<?xml version="1.0" ?>
<sdf version="1.5">
  <model name="Hinged_door_standard">
    <link name="frame">
      <pose>0.06 -0.0005 0 0 0 0</pose>
      <collision name="Door_frame_hinge_side_collison">
        <pose>-0.025145 -0.03429 1.0541 0 0 0</pose>
        <geometry>
          <box>
            <size>0.05029 0.06858 2.10820</size>
          </box>
        </geometry>
      </collision>
      <collision name="Door_frame_lockside_front_collision">
        <pose>-0.05145 0.954631 1.0541 0 0 0</pose>
        <geometry>
          <box>
            <size>0.00005 0.06858 2.10820</size>
          </box>
        </geometry>
      </collision>
      <collision name="Door_frame_lockside_back_collision">
        <pose>0.0 0.954631 1.0541 0 0 0</pose>
        <geometry>
          <box>
            <size>0.00005 0.06858 2.10820</size>
          </box>
        </geometry>
      </collision>
      <collision name="Door_frame_top_collision">
        <pose>0 0.5 2.08 0 0 0</pose>
        <geometry>
          <box>
            <size> 0.1005 0.95 0.06858 </size>
          </box>
        </geometry>
      </collision>
      <visual name="visual front">
        <pose>0 -0.06858 0 0 0 0</pose>
        <geometry>
          <mesh>
            <uri>file:///home/jacob/user_ws/src/simulation/tiplu_world/models/Hinged_door_standard/meshes/frame.dae</uri>
            <scale>1 1 1</scale>
          </mesh>
        </geometry>
      </visual>
    </link>
    <link name="door">
      <pose>-0.0 0.000 2.040 3.14159 0 1.57</pose>
      <inertial>
        <mass>41.3256</mass>
        <pose>0.4569 0.0349 1.016 0 0 0</pose>
        <inertia>
          <ixx>14.2053</ixx>
          <ixy>0.0004</ixy>
          <ixz>0.0000</ixz>
          <iyy>17.1997</iyy>
          <iyz>0.0000</iyz>
          <izz>3.0298</izz>
        </inertia>
      </inertial>
      <collision name="door_leaf_side_a_collision">
        <pose>0.4569 0.00549 1.016 0 0 0</pose>
        <geometry>
          <box>
            <size>0.9144 0.00004 2.032</size>
          </box>
        </geometry>
      </collision>
      <collision name="door_leaf_side_b_collision">
        <pose>0.4569 -0.0549 1.016 0 0 0</pose>
        <geometry>
          <box>
            <size>0.9144 0.00004 2.032</size>
          </box>
        </geometry>
      </collision>
      <visual name="visual">
        <pose>0 -0.06858 0 0 0 0</pose>
        <geometry>
          <mesh>
            <uri>file:///home/jacob/user_ws/src/simulation/tiplu_world/models/Hinged_door_standard/meshes/door.dae</uri>
            <scale>1 1 1</scale>
          </mesh>
        </geometry>
      </visual>
    </link>
    <link name="handles">
      <pose>0.0 0.8 1.05 0 3.14 1.57</pose>
      <collision name="handle_connecting_rood_collision">
        <pose>0 -0.015 0 -1.6 0 0</pose>
        <geometry>
          <cylinder>
            <radius>0.01</radius>
            <length>0.29</length>
          </cylinder>
        </geometry>
      </collision>
      <visual name="handle_connecting_rood_visual">
        <pose>0 -0.015 0 -1.6 0 0</pose>
        <geometry>
          <cylinder>
            <radius>0.01</radius>
            <length>0.29</length>
          </cylinder>
        </geometry>
      </visual>
      <visual name="handle_bold_visual">
        <pose> -0.08 -0.028 0.01 0 1.64 0</pose>
        <geometry>
          <cylinder>
            <radius>0.005</radius>
            <length>0.14</length>
          </cylinder>
        </geometry>
      </visual>
      <collision name="handle_bold_collision">
           <pose> -0.08 -0.028 0.01 0 1.64 0</pose>
        <geometry>
          <cylinder>
            <radius>0.005</radius>
            <length>0.14</length>
          </cylinder>
        </geometry>
      </collision>
      <collision name="handle1_handpiece_side_b_collision">
        <pose>0.1  -0.13 0 -1.57 0 -1.5</pose>
        <geometry>
          <cylinder>
            <radius>0.02</radius>
            <length>0.2</length>
          </cylinder>
        </geometry>
      </collision>
      <visual name="handle1_handpiece_side_b_visual">
        <pose>0.1 -0.13 0 -1.57 0 -1.5</pose>
        <geometry>
          <cylinder>
            <radius>0.02</radius>
            <length>0.2</length>
          </cylinder>
        </geometry>
      </visual>
      <collision name="handle1_handpiece_side_a_collision">
        <pose>0.1  0.13 0 -1.57 0 -1.5</pose>
        <geometry>
          <cylinder>
            <radius>0.02</radius>
            <length>0.2</length>
          </cylinder>
        </geometry>
      </collision>
      <visual name="handle1_handpiece_side_a_visual">
        <pose>0.1  0.13 0 -1.57 0 -1.5</pose>
        <geometry>
          <cylinder>
            <radius>0.02</radius>
            <length>0.2</length>
          </cylinder>
        </geometry>
      </visual>

    </link>
    <joint name="handle" type="revolute">
      <parent>door</parent>
      <child>handles</child>
      <pose>0.015 0 0 0 0 0</pose>
      <axis>
        <xyz>1 0 0</xyz>
        <limit>
          <lower>0</lower>
          <upper>1</upper>
        </limit>

        <dynamics>
          <spring_stiffness>50</spring_stiffness>
          <spring_reference>0.0</spring_reference>
          <damping>1.0</damping>
          <friction>10</friction>
        </dynamics>
        <use_parent_model_frame>true</use_parent_model_frame>
      </axis>
      <physics>
        <ode>
          <cfm_damping>1</cfm_damping>
        </ode>
      </physics>
    </joint>
      <plugin filename="libgz-sim-joint-position-controller-system.so" name="gz::sim::systems::JointPositionController">
        <joint_name>handle</joint_name>
        <p_gain>500</p_gain>
        <i_gain>1000</i_gain>
        <d_gain>10</d_gain>
        <i_max>200</i_max>
        <i_min>-200</i_min>
        <cmd_max>1000</cmd_max>
        <cmd_min>-1000</cmd_min>
      </plugin>
    <joint name="hinge" type="revolute">
      <parent>frame</parent>
      <child>door</child>
      <axis>
        <xyz>0 0 1</xyz>
        <limit>
          <lower>0</lower>
          <!-- <lower>-1.58</lower> -->
          <upper>1.58</upper>
        </limit>
        <dynamics>
          <damping>1.0</damping>
          <friction>10.0</friction>
        </dynamics>
        <use_parent_model_frame>true</use_parent_model_frame>
      </axis>
      <physics>
        <ode>
          <cfm_damping>1</cfm_damping>
        </ode>
      </physics>
    </joint>
      <plugin filename="libgz-sim-joint-position-controller-system.so" name="gz::sim::systems::JointPositionController">
        <joint_name>hinge</joint_name>
        <p_gain>500</p_gain>
        <i_gain>1000</i_gain>
        <d_gain>10</d_gain>
        <i_max>200</i_max>
        <i_min>-200</i_min>
        <cmd_max>1000</cmd_max>
        <cmd_min>-1000</cmd_min>
      </plugin>

    <joint name="world_joint" type="fixed">
      <child>frame</child>
      <parent>world</parent>
      <axis>
        <limit>
          <lower>0</lower>
          <upper>0</upper>
        </limit>
        <xyz>0 1 0</xyz>
        <dynamics>
          <damping>1.0</damping>
        </dynamics>
        <use_parent_model_frame>true</use_parent_model_frame>
      </axis>
      <physics>
        <ode>
          <cfm_damping>1</cfm_damping>
        </ode>
      </physics>
    </joint>
  </model>
</sdf>
