<?xml version="1.0" encoding="utf-8"?>
<sdf version='1.7'>
  <model name='rb_theron'>
    <link name='base_footprint'>
      <inertial>
        <pose>-0.111833 2e-06 0.063888 0 -0 0</pose>
        <mass>51.121</mass>
        <inertia>
          <ixx>2.03814</ixx>
          <ixy>-3.87042e-05</ixy>
          <ixz>-0.0617609</ixz>
          <iyy>2.74275</iyy>
          <iyz>-1.76323e-05</iyz>
          <izz>2.71767</izz>
        </inertia>
      </inertial>
      <collision name='base_footprint_fixed_joint_lump__base_link_collision'>
        <pose>0 0 0.0606 0 -0 0</pose>
        <geometry>
          <mesh>
            <scale>1 1 1</scale>
            <uri>model://rb_theron/meshes/bases/theron_base.stl</uri>
          </mesh>
        </geometry>
        <surface>
          <contact>
            <ode/>
          </contact>
          <friction>
            <ode/>
          </friction>
        </surface>
      </collision>
      <collision name='base_footprint_fixed_joint_lump__bottom_cover_link_collision_1'>
        <pose>0 0 0.0606 0 -0 0</pose>
        <geometry>
          <mesh>
            <scale>1 1 1</scale>
            <uri>model://rb_theron/meshes/bases/mcq_prototype_bottom_cover.dae</uri>
          </mesh>
        </geometry>
      </collision>
      <collision name='base_footprint_fixed_joint_lump__front_laser_base_link_collision_2'>
        <pose>0.25 0 0.2249 3.14159 -7e-06 7e-06</pose>
        <geometry>
          <mesh>
            <scale>1 1 1</scale>
            <uri>model://rb_theron/meshes/sensors/sick_nanoscan3.dae</uri>
          </mesh>
        </geometry>
      </collision>
      <collision name='base_footprint_fixed_joint_lump__front_realsense_camera_camera_link_collision_3'>
        <pose>0.318 0 0.2074 0 -0 0</pose>
        <geometry>
          <box>
            <size>0.025 0.1 0.025</size>
          </box>
        </geometry>
        <surface>
          <contact>
            <ode/>
          </contact>
          <friction>
            <ode/>
          </friction>
        </surface>
      </collision>
      <collision name='base_footprint_fixed_joint_lump__front_rgbd_camera_link_collision_4'>
        <pose>0.3305 0 0.2504 0 -0 0</pose>
        <geometry>
          <mesh>
            <scale>1 1 1</scale>
            <uri>model://rb_theron/meshes/sensors/orbbec_astra.dae</uri>
          </mesh>
        </geometry>
        <surface>
          <contact>
            <ode/>
          </contact>
          <friction>
            <ode/>
          </friction>
        </surface>
      </collision>
      <collision name='base_footprint_fixed_joint_lump__top_laser_base_link_collision_5'>
        <pose>0.25 0 0.2896 4.71238898038 0 0</pose>
        <geometry>
          <mesh>
            <scale>1 1 1</scale>
            <uri>model://rb_theron/meshes/sensors/robosense_16.dae</uri>
          </mesh>
        </geometry>
      </collision>
      <!--<collision name='base_footprint_fixed_joint_lump__imu_link_collision_6'>
        <pose>-0.1975 0 0.2204 0 -0 0</pose>
        <geometry>
          <box>
            <size>0.001 0.001 0.001</size>
          </box>
        </geometry>
      </collision> -->
      <visual name='base_footprint_visual'>
        <pose>0 0 0 0 -0 0</pose>
        <geometry>
          <box>
            <size>0.001 0.001 0.001</size>
          </box>
        </geometry>
        <material>
          <script>
            <name>Gazebo/Green</name>
            <uri>file://media/materials/scripts/gazebo.material</uri>
          </script>
        </material>
      </visual>
      <visual name='base_footprint_fixed_joint_lump__base_link_visual_1'>
        <pose>0 0 0.0606 0 -0 0</pose>
        <geometry>
          <mesh>
            <scale>1 1 1</scale>
            <uri>model://rb_theron/meshes/bases/theron_base.stl</uri>
          </mesh>
        </geometry>
        <material>
          <script>
            <name>Gazebo/DarkGrey</name>
            <uri>file://media/materials/scripts/gazebo.material</uri>
          </script>
        </material>
      </visual>
      <visual name='base_footprint_fixed_joint_lump__bottom_cover_link_visual_2'>
        <pose>0 0 0.0606 0 -0 0</pose>
        <geometry>
          <mesh>
            <scale>1 1 1</scale>
            <uri>model://rb_theron/meshes/bases/mcq_prototype_bottom_cover.dae</uri>
          </mesh>
        </geometry>
        <material>
          <script>
            <name>Gazebo/DarkGrey</name>
            <uri>file://media/materials/scripts/gazebo.material</uri>
          </script>
        </material>
      </visual>
      <visual name='base_footprint_fixed_joint_lump__front_laser_base_link_visual_3'>
        <pose>0.25 0 0.2249 3.14159 -7e-06 7e-06</pose>
        <geometry>
          <mesh>
            <scale>1 1 1</scale>
            <uri>model://rb_theron/meshes/sensors/sick_nanoscan3.dae</uri>
          </mesh>
        </geometry>
      </visual>
      <visual name='base_footprint_fixed_joint_lump__front_realsense_camera_camera_link_visual_4'>
        <pose>0.3305 0 0.2074 0 -0 0</pose>
        <geometry>
          <mesh>
            <scale>1 1 1</scale>
            <uri>model://rb_theron/meshes/sensors/intel_r430.dae</uri>
          </mesh>
        </geometry>
      </visual>
      <visual name='base_footprint_fixed_joint_lump__front_rgbd_camera_link_visual_5'>
        <pose>0.3305 0 0.2504 0 -0 0</pose>
        <geometry>
          <mesh>
            <scale>1 1 1</scale>
            <uri>model://rb_theron/meshes/sensors/orbbec_astra.dae</uri>
          </mesh>
        </geometry>
      </visual>
      <visual name='base_footprint_fixed_joint_lump__front_top_laser_base_link_visual_6'>
        <pose>0.25 0 0.2896 4.71238898038 0 0 </pose>
        <geometry>
          <mesh>
            <scale>1 1 1</scale>
            <uri>model://rb_theron/meshes/sensors/robosense_16.dae</uri>
          </mesh>
        </geometry>
      </visual>
      <visual name='base_footprint_fixed_joint_lump__imu_link_visual_7'>
        <pose>-0.1975 0 0.2204 0 -0 0</pose>
        <geometry>
          <box>
            <size>0.001 0.001 0.001</size>
          </box>
        </geometry>
      </visual>
      <velocity_decay/>
      <velocity_decay/>
      <velocity_decay/>
      <sensor name='front_laser_sensor' type='ray'>
        <visualize>0</visualize>
        <update_rate>12.5</update_rate>
        <ray>
          <scan>
            <horizontal>
              <samples>1618</samples>
              <resolution>1</resolution>
              <min_angle>-1.9507619</min_angle> <!-- -2.0507619 -->
            <max_angle>1.9507619</max_angle> <!-- 2.0507619 -->
            </horizontal>
          </scan>
          <range>
            <min>0.065</min>
            <max>40</max>
            <resolution>0.07</resolution>
          </range>
          <noise>
            <type>gaussian</type>
            <mean>0</mean>
            <stddev>0.03</stddev>
          </noise>
        </ray>
        <plugin name='front_laser_controller' filename='libgazebo_ros_ray_sensor.so'>
          <!-- <topicName>front_laser/scan</topicName> -->
		      <ros>
            <remapping>~/out:=scan</remapping>
          </ros>
          <frameName>front_laser_link</frameName>
		      <output_type>sensor_msgs/LaserScan</output_type>
        </plugin>
        <pose>0.25 0 0.1744 0 -7e-06 7e-06</pose>
      </sensor>
      <sensor name='robosense-RS16' type='gpu_ray'>
        <visualize>0</visualize>
        <update_rate>20</update_rate>
        <ray>
          <scan>
            <horizontal>
              <samples>900</samples>
              <resolution>1</resolution>
              <min_angle>-3.14159</min_angle>
              <max_angle>3.14159</max_angle>
            </horizontal>
            <vertical>
              <samples>16</samples>
              <resolution>1</resolution>
              <min_angle>-0.261799</min_angle>
              <max_angle>0.261799</max_angle>
            </vertical>
          </scan>
          <range>
            <min>0.4</min>
            <max>151</max>
            <resolution>0.001</resolution>
          </range>
          <noise>
            <type>gaussian</type>
            <mean>0</mean>
            <stddev>0.008</stddev>
          </noise>
        </ray>
        <pose>0 0 0.489 0 -0 0</pose>
      </sensor>
      <velocity_decay/>
      

      <sensor name="cameradepth" type="depth">
        <camera name="camera">
          <horizontal_fov>1.57</horizontal_fov>
          <image>
            <width>1280</width>
            <height>720</height>
          </image>
          <clip>
            <near>0.1</near>
            <far>100</far>
          </clip>
          <noise>
            <type>gaussian</type>
            <mean>0.0</mean>
            <stddev>0.100</stddev>
          </noise>
        </camera>
        <always_on>1</always_on>
        <update_rate>30</update_rate>
        <visualize>0</visualize>
      </sensor>
      <sensor name="cameracolor" type="camera">
        <camera name="camera">
          <horizontal_fov>1.57</horizontal_fov>
          <image>
            <width>1280</width>
            <height>720</height>
            <format>RGB_INT8</format>
          </image>
          <clip>
            <near>0.1</near>
            <far>100</far>
          </clip>
          <noise>
            <type>gaussian</type>
            <mean>0.0</mean>
            <stddev>0.007</stddev>
          </noise>
        </camera>
        <always_on>1</always_on>
        <update_rate>30</update_rate>
        <visualize>1</visualize>
      </sensor>
      <sensor name="cameraired1" type="camera">
        <camera name="camera">
          <horizontal_fov>1.57</horizontal_fov>
          <image>
            <width>1280</width>
            <height>720</height>
            <format>L_INT8</format>
          </image>
          <clip>
            <near>0.1</near>
            <far>100</far>
          </clip>
          <noise>
            <type>gaussian</type>
            <mean>0.0</mean>
            <stddev>0.05</stddev>
          </noise>
        </camera>
        <always_on>1</always_on>
        <update_rate>1</update_rate>
        <visualize>0</visualize>
      </sensor>
      <sensor name="cameraired2" type="camera">
        <camera name="camera">
          <horizontal_fov>1.57</horizontal_fov>
          <image>
            <width>1280</width>
            <height>720</height>
            <format>L_INT8</format>
          </image>
          <clip>
            <near>0.1</near>
            <far>100</far>
          </clip>
          <noise>
            <type>gaussian</type>
            <mean>0.0</mean>
            <stddev>0.05</stddev>
          </noise>
        </camera>
        <always_on>1</always_on>
        <update_rate>1</update_rate>
        <visualize>0</visualize>
      </sensor>

      <gravity>1</gravity>
      <velocity_decay/>
      <sensor name='front_rgbd_camera_depth_sensor' type='depth'>
        <always_on>1</always_on>
        <update_rate>20</update_rate>
        <camera>
          <horizontal_fov>1.0472</horizontal_fov>
          <image>
            <format>R8G8B8</format>
            <width>640</width>
            <height>480</height>
          </image>
          <clip>
            <near>0.05</near>
            <far>3.5</far>
          </clip>
        </camera>
        <plugin name='front_rgbd_camera_controller' filename='libgazebo_ros_openni_kinect.so'>
          <cameraName>front_rgbd_camera</cameraName>
          <alwaysOn>1</alwaysOn>
          <updateRate>10</updateRate>
          <imageTopicName>rgb/image_raw</imageTopicName>
          <depthImageTopicName>depth/image_raw</depthImageTopicName>
          <pointCloudTopicName>depth/points</pointCloudTopicName>
          <cameraInfoTopicName>rgb/camera_info</cameraInfoTopicName>
          <depthImageCameraInfoTopicName>depth/camera_info</depthImageCameraInfoTopicName>
          <frameName>/front_rgbd_camera_depth_optical_frame</frameName>
          <baseline>0.1</baseline>
          <distortion_k1>0.0</distortion_k1>
          <distortion_k2>0.0</distortion_k2>
          <distortion_k3>0.0</distortion_k3>
          <distortion_t1>0.0</distortion_t1>
          <distortion_t2>0.0</distortion_t2>
          <pointCloudCutoff>0.4</pointCloudCutoff>
        </plugin>
        <pose>0.3305 0 0.2504 0 -0 0</pose>
      </sensor>
    </link>
    <joint name='leftjoint_rsupport' type='revolute'>
      <pose relative_to='base_footprint'>0.1175 0.1725 0.1034 0 -0 0</pose>
      <parent>base_footprint</parent>
      <child>leftrsupport</child>
      <axis>
        <xyz>0 1 0</xyz>
        <limit>
          <lower>-0.5</lower>
          <upper>0.5</upper>
          <effort>100</effort>
          <velocity>100</velocity>
        </limit>
        <dynamics>
          <spring_reference>0</spring_reference>
          <spring_stiffness>0</spring_stiffness>
        </dynamics>
      </axis>
    </joint>
    <link name='leftrsupport'>
      <pose relative_to='leftjoint_rsupport'>0 0 0 0 -0 0</pose>
      <inertial>
        <pose>0 0 0 0 -0 0</pose>
        <mass>1.5</mass>
        <inertia>
          <ixx>5e-05</ixx>
          <ixy>0</ixy>
          <ixz>0</ixz>
          <iyy>5e-05</iyy>
          <iyz>0</iyz>
          <izz>7.5e-05</izz>
        </inertia>
      </inertial>
      <collision name='leftrsupport_collision'>
        <pose>0 0 0 0 -0 0</pose>
        <geometry>
          <mesh>
            <scale>1 1 1</scale>
            <uri>model://rb_theron/meshes/rocker/mcq_prototype_rocker_l.dae</uri>
          </mesh>
        </geometry>
      </collision>
      <visual name='leftrsupport_visual'>
        <pose>0 0 0 0 -0 0</pose>
        <geometry>
          <mesh>
            <scale>1 1 1</scale>
            <uri>model://rb_theron/meshes/rocker/mcq_prototype_rocker_l.dae</uri>
          </mesh>
        </geometry>
      </visual>
    </link>
    <joint name='left_wheel_joint' type='revolute'>
      <pose relative_to='leftrsupport'>-0.1175 0.079 -0.0428 0 -0 0</pose>
      <parent>leftrsupport</parent>
      <child>left_wheel_link</child>
      <axis>
        <xyz>0 1 0</xyz>
        <limit>
          <lower>-1e+16</lower>
          <upper>1e+16</upper>
        </limit>
        <dynamics>
          <spring_reference>0</spring_reference>
          <spring_stiffness>0</spring_stiffness>
        </dynamics>
      </axis>
    </joint>
    <link name='left_wheel_link'>
      <pose relative_to='left_wheel_joint'>0 0 0 0 -0 0</pose>
      <inertial>
        <pose>0 0 0 0 -0 0</pose>
        <mass>0.25</mass>
        <inertia>
          <ixx>0.000370231</ixx>
          <ixy>0</ixy>
          <ixz>0</ixz>
          <iyy>0.000370231</iyy>
          <iyz>0</iyz>
          <izz>0.00071442</izz>
        </inertia>
      </inertial>
      <collision name='left_wheel_link_collision'>
        <pose>0 0 0 1.5708 -0 0</pose>
        <geometry>
          <cylinder>
            <length>0.025</length>
            <radius>0.0756</radius>
          </cylinder>
        </geometry>
        <surface>
          <contact>
            <ode>
              <kp>500000</kp>
              <kd>1</kd>
            </ode>
          </contact>
          <friction>
            <ode>
              <mu>100</mu>
              <mu2>100</mu2>
            </ode>
          </friction>
        </surface>
      </collision>
      <visual name='left_wheel_link_visual'>
        <pose>0 0 0 1.5708 -0 0</pose>
        <geometry>
          <cylinder>
            <length>0.025</length>
            <radius>0.0756</radius>
          </cylinder>
        </geometry>
        <material>
          <script>
            <name>Gazebo/Yellow</name>
            <uri>file://media/materials/scripts/gazebo.material</uri>
          </script>
        </material>
      </visual>
      <gravity>1</gravity>
      <velocity_decay/>
    </link>
    <joint name='leftcastorjoint_support' type='revolute'>
      <pose relative_to='leftrsupport'>0.1175 0.01 0.002 0 -0 0</pose>
      <parent>leftrsupport</parent>
      <child>leftcastorsupport</child>
      <axis>
        <xyz>0 0 1</xyz>
        <limit>
          <lower>-1e+16</lower>
          <upper>1e+16</upper>
        </limit>
        <dynamics>
          <damping>0</damping>
          <friction>0.01</friction>
          <spring_reference>0</spring_reference>
          <spring_stiffness>0</spring_stiffness>
        </dynamics>
      </axis>
    </joint>
    <link name='leftcastorsupport'>
      <pose relative_to='leftcastorjoint_support'>0 0 0 0 -0 0</pose>
      <inertial>
        <pose>0 0 0 0 -0 0</pose>
        <mass>1.5</mass>
        <inertia>
          <ixx>5e-05</ixx>
          <ixy>0</ixy>
          <ixz>0</ixz>
          <iyy>5e-05</iyy>
          <iyz>0</iyz>
          <izz>7.5e-05</izz>
        </inertia>
      </inertial>
      <collision name='leftcastorsupport_collision'>
        <pose>0 0 0 0 -0 0</pose>
        <geometry>
          <mesh>
            <scale>1 1 1</scale>
            <uri>model://rb_theron/meshes/wheels/mcq_prototype_base_castor.dae</uri>
          </mesh>
        </geometry>
      </collision>
      <visual name='leftcastorsupport_visual'>
        <pose>0 0 0 0 -0 0</pose>
        <geometry>
          <mesh>
            <scale>1 1 1</scale>
            <uri>model://rb_theron/meshes/wheels/mcq_prototype_base_castor.dae</uri>
          </mesh>
        </geometry>
      </visual>
    </link>
    <joint name='leftcastorjoint_wheel' type='revolute'>
      <pose relative_to='leftcastorsupport'>-0.033 0 -0.071 0 -0 0</pose>
      <parent>leftcastorsupport</parent>
      <child>leftcastorwheel</child>
      <axis>
        <xyz>0 1 0</xyz>
        <limit>
          <lower>-1e+16</lower>
          <upper>1e+16</upper>
        </limit>
        <dynamics>
          <spring_reference>0</spring_reference>
          <spring_stiffness>0</spring_stiffness>
        </dynamics>
      </axis>
    </joint>
    <link name='leftcastorwheel'>
      <pose relative_to='leftcastorjoint_wheel'>0 0 0 0 -0 0</pose>
      <inertial>
        <pose>0 0 0 0 -0 0</pose>
        <mass>0.25</mass>
        <inertia>
          <ixx>0.000169271</ixx>
          <ixy>0</ixy>
          <ixz>0</ixz>
          <iyy>0.000169271</iyy>
          <iyz>0</iyz>
          <izz>0.0003125</izz>
        </inertia>
      </inertial>
      <collision name='leftcastorwheel_collision'>
        <pose>0 0 0 1.5708 -0 0</pose>
        <geometry>
          <cylinder>
            <length>0.025</length>
            <radius>0.05</radius>
          </cylinder>
        </geometry>
      </collision>
      <visual name='leftcastorwheel_visual'>
        <pose>0 0 0 1.5708 -0 0</pose>
        <geometry>
          <cylinder>
            <length>0.025</length>
            <radius>0.05</radius>
          </cylinder>
        </geometry>
      </visual>
    </link>
    <joint name='leftjoint_support' type='revolute'>
      <pose relative_to='base_footprint'>-0.235 0.1725 0.1034 0 -0 0</pose>
      <parent>base_footprint</parent>
      <child>leftsupport</child>
      <axis>
        <xyz>0 0 1</xyz>
        <limit>
          <lower>-1e+16</lower>
          <upper>1e+16</upper>
        </limit>
        <dynamics>
          <damping>0</damping>
          <friction>0.01</friction>
          <spring_reference>0</spring_reference>
          <spring_stiffness>0</spring_stiffness>
        </dynamics>
      </axis>
    </joint>
    <link name='leftsupport'>
      <pose relative_to='leftjoint_support'>0 0 0 0 -0 0</pose>
      <inertial>
        <pose>0 0 0 0 -0 0</pose>
        <mass>1.5</mass>
        <inertia>
          <ixx>5e-05</ixx>
          <ixy>0</ixy>
          <ixz>0</ixz>
          <iyy>5e-05</iyy>
          <iyz>0</iyz>
          <izz>7.5e-05</izz>
        </inertia>
      </inertial>
      <collision name='leftsupport_collision'>
        <pose>0 0 0 0 -0 0</pose>
        <geometry>
          <mesh>
            <scale>1 1 1</scale>
            <uri>model://rb_theron/meshes/wheels/mcq_prototype_base_castor.dae</uri>
          </mesh>
        </geometry>
      </collision>
      <visual name='leftsupport_visual'>
        <pose>0 0 0 0 -0 0</pose>
        <geometry>
          <mesh>
            <scale>1 1 1</scale>
            <uri>model://rb_theron/meshes/wheels/mcq_prototype_base_castor.dae</uri>
          </mesh>
        </geometry>
      </visual>
    </link>
    <joint name='leftjoint_wheel' type='revolute'>
      <pose relative_to='leftsupport'>-0.033 0 -0.071 0 -0 0</pose>
      <parent>leftsupport</parent>
      <child>leftwheel</child>
      <axis>
        <xyz>0 1 0</xyz>
        <limit>
          <lower>-1e+16</lower>
          <upper>1e+16</upper>
        </limit>
        <dynamics>
          <spring_reference>0</spring_reference>
          <spring_stiffness>0</spring_stiffness>
        </dynamics>
      </axis>
    </joint>
    <link name='leftwheel'>
      <pose relative_to='leftjoint_wheel'>0 0 0 0 -0 0</pose>
      <inertial>
        <pose>0 0 0 0 -0 0</pose>
        <mass>0.25</mass>
        <inertia>
          <ixx>0.000169271</ixx>
          <ixy>0</ixy>
          <ixz>0</ixz>
          <iyy>0.000169271</iyy>
          <iyz>0</iyz>
          <izz>0.0003125</izz>
        </inertia>
      </inertial>
      <collision name='leftwheel_collision'>
        <pose>0 0 0 1.5708 -0 0</pose>
        <geometry>
          <cylinder>
            <length>0.025</length>
            <radius>0.05</radius>
          </cylinder>
        </geometry>
      </collision>
      <visual name='leftwheel_visual'>
        <pose>0 0 0 1.5708 -0 0</pose>
        <geometry>
          <cylinder>
            <length>0.025</length>
            <radius>0.05</radius>
          </cylinder>
        </geometry>
      </visual>
    </link>
    <joint name='rightjoint_rsupport' type='revolute'>
      <pose relative_to='base_footprint'>0.1175 -0.1725 0.1034 0 -0 0</pose>
      <parent>base_footprint</parent>
      <child>rightrsupport</child>
      <axis>
        <xyz>0 1 0</xyz>
        <limit>
          <lower>-0.5</lower>
          <upper>0.5</upper>
          <effort>100</effort>
          <velocity>100</velocity>
        </limit>
        <dynamics>
          <spring_reference>0</spring_reference>
          <spring_stiffness>0</spring_stiffness>
        </dynamics>
      </axis>
    </joint>
    <link name='rightrsupport'>
      <pose relative_to='rightjoint_rsupport'>0 0 0 0 -0 0</pose>
      <inertial>
        <pose>0 0 0 0 -0 0</pose>
        <mass>1.5</mass>
        <inertia>
          <ixx>5e-05</ixx>
          <ixy>0</ixy>
          <ixz>0</ixz>
          <iyy>5e-05</iyy>
          <iyz>0</iyz>
          <izz>7.5e-05</izz>
        </inertia>
      </inertial>
      <collision name='rightrsupport_collision'>
        <pose>0 0 0 0 -0 0</pose>
        <geometry>
          <mesh>
            <scale>1 1 1</scale>
            <uri>model://rb_theron/meshes/rocker/mcq_prototype_rocker_r.dae</uri>
          </mesh>
        </geometry>
      </collision>
      <visual name='rightrsupport_visual'>
        <pose>0 0 0 0 -0 0</pose>
        <geometry>
          <mesh>
            <scale>1 1 1</scale>
            <uri>model://rb_theron/meshes/rocker/mcq_prototype_rocker_r.dae</uri>
          </mesh>
        </geometry>
      </visual>
    </link>
    <joint name='right_wheel_joint' type='revolute'>
      <pose relative_to='rightrsupport'>-0.1175 -0.079 -0.0428 0 -0 0</pose>
      <parent>rightrsupport</parent>
      <child>right_wheel_link</child>
      <axis>
        <xyz>0 1 0</xyz>
        <limit>
          <lower>-1e+16</lower>
          <upper>1e+16</upper>
        </limit>
        <dynamics>
          <spring_reference>0</spring_reference>
          <spring_stiffness>0</spring_stiffness>
        </dynamics>
      </axis>
    </joint>
    <link name='right_wheel_link'>
      <pose relative_to='right_wheel_joint'>0 0 0 0 -0 0</pose>
      <inertial>
        <pose>0 0 0 0 -0 0</pose>
        <mass>0.25</mass>
        <inertia>
          <ixx>0.000370231</ixx>
          <ixy>0</ixy>
          <ixz>0</ixz>
          <iyy>0.000370231</iyy>
          <iyz>0</iyz>
          <izz>0.00071442</izz>
        </inertia>
      </inertial>
      <collision name='right_wheel_link_collision'>
        <pose>0 0 0 1.5708 -0 0</pose>
        <geometry>
          <cylinder>
            <length>0.025</length>
            <radius>0.0756</radius>
          </cylinder>
        </geometry>
        <surface>
          <contact>
            <ode>
              <kp>500000</kp>
              <kd>1</kd>
            </ode>
          </contact>
          <friction>
            <ode>
              <mu>100</mu>
              <mu2>100</mu2>
            </ode>
          </friction>
        </surface>
      </collision>
      <visual name='right_wheel_link_visual'>
        <pose>0 0 0 1.5708 -0 0</pose>
        <geometry>
          <cylinder>
            <length>0.025</length>
            <radius>0.0756</radius>
          </cylinder>
        </geometry>
        <material>
          <script>
            <name>Gazebo/Yellow</name>
            <uri>file://media/materials/scripts/gazebo.material</uri>
          </script>
        </material>
      </visual>
      <gravity>1</gravity>
      <velocity_decay/>
    </link>
    <joint name='rightcastorjoint_support' type='revolute'>
      <pose relative_to='rightrsupport'>0.1175 -0.01 0.002 0 -0 0</pose>
      <parent>rightrsupport</parent>
      <child>rightcastorsupport</child>
      <axis>
        <xyz>0 0 1</xyz>
        <limit>
          <lower>-1e+16</lower>
          <upper>1e+16</upper>
        </limit>
        <dynamics>
          <damping>0</damping>
          <friction>0.01</friction>
          <spring_reference>0</spring_reference>
          <spring_stiffness>0</spring_stiffness>
        </dynamics>
      </axis>
    </joint>
    <link name='rightcastorsupport'>
      <pose relative_to='rightcastorjoint_support'>0 0 0 0 -0 0</pose>
      <inertial>
        <pose>0 0 0 0 -0 0</pose>
        <mass>1.5</mass>
        <inertia>
          <ixx>5e-05</ixx>
          <ixy>0</ixy>
          <ixz>0</ixz>
          <iyy>5e-05</iyy>
          <iyz>0</iyz>
          <izz>7.5e-05</izz>
        </inertia>
      </inertial>
      <collision name='rightcastorsupport_collision'>
        <pose>0 0 0 0 -0 0</pose>
        <geometry>
          <mesh>
            <scale>1 1 1</scale>
            <uri>model://rb_theron/meshes/wheels/mcq_prototype_base_castor.dae</uri>
          </mesh>
        </geometry>
      </collision>
      <visual name='rightcastorsupport_visual'>
        <pose>0 0 0 0 -0 0</pose>
        <geometry>
          <mesh>
            <scale>1 1 1</scale>
            <uri>model://rb_theron/meshes/wheels/mcq_prototype_base_castor.dae</uri>
          </mesh>
        </geometry>
      </visual>
    </link>
    <joint name='rightcastorjoint_wheel' type='revolute'>
      <pose relative_to='rightcastorsupport'>-0.033 0 -0.071 0 -0 0</pose>
      <parent>rightcastorsupport</parent>
      <child>rightcastorwheel</child>
      <axis>
        <xyz>0 1 0</xyz>
        <limit>
          <lower>-1e+16</lower>
          <upper>1e+16</upper>
        </limit>
        <dynamics>
          <spring_reference>0</spring_reference>
          <spring_stiffness>0</spring_stiffness>
        </dynamics>
      </axis>
    </joint>
    <link name='rightcastorwheel'>
      <pose relative_to='rightcastorjoint_wheel'>0 0 0 0 -0 0</pose>
      <inertial>
        <pose>0 0 0 0 -0 0</pose>
        <mass>0.25</mass>
        <inertia>
          <ixx>0.000169271</ixx>
          <ixy>0</ixy>
          <ixz>0</ixz>
          <iyy>0.000169271</iyy>
          <iyz>0</iyz>
          <izz>0.0003125</izz>
        </inertia>
      </inertial>
      <collision name='rightcastorwheel_collision'>
        <pose>0 0 0 1.5708 -0 0</pose>
        <geometry>
          <cylinder>
            <length>0.025</length>
            <radius>0.05</radius>
          </cylinder>
        </geometry>
      </collision>
      <visual name='rightcastorwheel_visual'>
        <pose>0 0 0 1.5708 -0 0</pose>
        <geometry>
          <cylinder>
            <length>0.025</length>
            <radius>0.05</radius>
          </cylinder>
        </geometry>
      </visual>
    </link>
    <joint name='rightjoint_support' type='revolute'>
      <pose relative_to='base_footprint'>-0.235 -0.1725 0.1034 0 -0 0</pose>
      <parent>base_footprint</parent>
      <child>rightsupport</child>
      <axis>
        <xyz>0 0 1</xyz>
        <limit>
          <lower>-1e+16</lower>
          <upper>1e+16</upper>
        </limit>
        <dynamics>
          <damping>0</damping>
          <friction>0.01</friction>
          <spring_reference>0</spring_reference>
          <spring_stiffness>0</spring_stiffness>
        </dynamics>
      </axis>
    </joint>
    <link name='rightsupport'>
      <pose relative_to='rightjoint_support'>0 0 0 0 -0 0</pose>
      <inertial>
        <pose>0 0 0 0 -0 0</pose>
        <mass>1.5</mass>
        <inertia>
          <ixx>5e-05</ixx>
          <ixy>0</ixy>
          <ixz>0</ixz>
          <iyy>5e-05</iyy>
          <iyz>0</iyz>
          <izz>7.5e-05</izz>
        </inertia>
      </inertial>
      <collision name='rightsupport_collision'>
        <pose>0 0 0 0 -0 0</pose>
        <geometry>
          <mesh>
            <scale>1 1 1</scale>
            <uri>model://rb_theron/meshes/wheels/mcq_prototype_base_castor.dae</uri>
          </mesh>
        </geometry>
      </collision>
      <visual name='rightsupport_visual'>
        <pose>0 0 0 0 -0 0</pose>
        <geometry>
          <mesh>
            <scale>1 1 1</scale>
            <uri>model://rb_theron/meshes/wheels/mcq_prototype_base_castor.dae</uri>
          </mesh>
        </geometry>
      </visual>
    </link>
    <joint name='rightjoint_wheel' type='revolute'>
      <pose relative_to='rightsupport'>-0.033 0 -0.071 0 -0 0</pose>
      <parent>rightsupport</parent>
      <child>rightwheel</child>
      <axis>
        <xyz>0 1 0</xyz>
        <limit>
          <lower>-1e+16</lower>
          <upper>1e+16</upper>
        </limit>
        <dynamics>
          <spring_reference>0</spring_reference>
          <spring_stiffness>0</spring_stiffness>
        </dynamics>
      </axis>
    </joint>
    <link name='rightwheel'>
      <pose relative_to='rightjoint_wheel'>0 0 0 0 -0 0</pose>
      <inertial>
        <pose>0 0 0 0 -0 0</pose>
        <mass>0.25</mass>
        <inertia>
          <ixx>0.000169271</ixx>
          <ixy>0</ixy>
          <ixz>0</ixz>
          <iyy>0.000169271</iyy>
          <iyz>0</iyz>
          <izz>0.0003125</izz>
        </inertia>
      </inertial>
      <collision name='rightwheel_collision'>
        <pose>0 0 0 1.5708 -0 0</pose>
        <geometry>
          <cylinder>
            <length>0.025</length>
            <radius>0.05</radius>
          </cylinder>
        </geometry>
      </collision>
      <visual name='rightwheel_visual'>
        <pose>0 0 0 1.5708 -0 0</pose>
        <geometry>
          <cylinder>
            <length>0.025</length>
            <radius>0.05</radius>
          </cylinder>
        </geometry>
      </visual>
    </link>
	<joint name="imu_joint" type="fixed">
      <parent>base_footprint</parent>
      <child>imu_link</child>
      <pose>-0.1975 0 0.2204 0 -0 0</pose>
      <axis>
        <xyz>0 0 1</xyz>
      </axis>
    </joint>    	
	<link name="imu_link">
      <sensor name="theron_imu" type="imu">
        <always_on>true</always_on>
        <update_rate>200</update_rate>
        <imu>
          <angular_velocity>
            <x>
              <noise type="gaussian">
                <mean>0.0</mean>
                <stddev>2e-4</stddev>
              </noise>
            </x>
            <y>
              <noise type="gaussian">
                <mean>0.0</mean>
                <stddev>2e-4</stddev>
              </noise>
            </y>
            <z>
              <noise type="gaussian">
                <mean>0.0</mean>
                <stddev>2e-4</stddev>
              </noise>
            </z>
          </angular_velocity>
          <linear_acceleration>
            <x>
              <noise type="gaussian">
                <mean>0.0</mean>
                <stddev>1.7e-2</stddev>
              </noise>
            </x>
            <y>
              <noise type="gaussian">
                <mean>0.0</mean>
                <stddev>1.7e-2</stddev>
              </noise>
            </y>
            <z>
              <noise type="gaussian">
                <mean>0.0</mean>
                <stddev>1.7e-2</stddev>
              </noise>
            </z>
          </linear_acceleration>
        </imu>
        <plugin name="imu" filename="libgazebo_ros_imu_sensor.so">
          <ros>
            <!-- <namespace>/tb3</namespace> -->
            <remapping>~/out:=imu</remapping>
          </ros>
        </plugin>
      </sensor>
    </link>	
	
    <plugin name='ros_control' filename='libgazebo_ros_control.so'>
      <robotParam>robot/description</robotParam>
      <controlPeriod>0.001</controlPeriod>
      <robotSimType>gazebo_ros_control/DefaultRobotHWSim</robotSimType>
      <legacyModeNS>1</legacyModeNS>
    </plugin>
	
    <static>0</static>
    
    <plugin name="diff_drive" filename="libgazebo_ros_diff_drive.so">
      <alwaysOn>1</alwaysOn>
	
	    <ros>
        <!-- <namespace>/tb3</namespace> -->
      </ros>

      <update_rate>30</update_rate>

      <!-- wheels -->
      <left_joint>left_wheel_joint</left_joint>
      <right_joint>right_wheel_joint</right_joint>

      <!-- kinematics -->
      <wheel_separation>0.500</wheel_separation>
      <wheel_diameter>0.1512</wheel_diameter>

      <!-- limits -->
      <max_wheel_torque>20</max_wheel_torque>
      <max_wheel_acceleration>1.0</max_wheel_acceleration>

      <command_topic>cmd_vel</command_topic>

      <!-- output -->
      <publish_odom>true</publish_odom>
      <publish_odom_tf>true</publish_odom_tf>
      <publish_wheel_tf>false</publish_wheel_tf>

      <odometry_topic>odom</odometry_topic>
      <odometry_frame>odom</odometry_frame>
      <base_frame>base_footprint</base_frame>
    </plugin>
	
	 <plugin name="joint_state" filename="libgazebo_ros_joint_state_publisher.so">
      <ros>
        <!-- <namespace>/tb3</namespace> -->
        <remapping>~/out:=joint_states</remapping>
      </ros>
	    <alwaysOn>1</alwaysOn>
      <update_rate>30</update_rate>

      <joint_name>leftjoint_rsupport</joint_name>
      <joint_name>rightjoint_rsupport</joint_name>

      <joint_name>left_wheel_joint</joint_name>
      <joint_name>right_wheel_joint</joint_name>

      <joint_name>leftcastorjoint_support</joint_name>
      <joint_name>rightcastorjoint_support</joint_name>

      <joint_name>leftcastorjoint_wheel</joint_name>
      <joint_name>rightcastorjoint_wheel</joint_name>

      <joint_name>leftjoint_support</joint_name>
      <joint_name>rightjoint_support</joint_name>

      <joint_name>leftjoint_wheel</joint_name>
      <joint_name>rightjoint_wheel</joint_name>
      
    </plugin>    

    <!-- <plugin name="camera" filename="librealsense_gazebo_plugin.so">
        <prefix>camera</prefix>
        <depthUpdateRate>30.0</depthUpdateRate>
        <colorUpdateRate>30.0</colorUpdateRate>
        <infraredUpdateRate>1.0</infraredUpdateRate>
        <depthTopicName>aligned_depth_to_color/image_raw</depthTopicName>
        <depthCameraInfoTopicName>depth/camera_info</depthCameraInfoTopicName>
        <colorTopicName>color/image_raw</colorTopicName>
        <colorCameraInfoTopicName>color/camera_info</colorCameraInfoTopicName>
        <infrared1TopicName>infra1/image_raw</infrared1TopicName>
        <infrared1CameraInfoTopicName>infra1/camera_info</infrared1CameraInfoTopicName>
        <infrared2TopicName>infra2/image_raw</infrared2TopicName>
        <infrared2CameraInfoTopicName>infra2/camera_info</infrared2CameraInfoTopicName>
        <colorOpticalframeName>front_realsense_camera_camera_depth_optical_frame</colorOpticalframeName>
        <depthOpticalframeName>front_realsense_camera_camera_depth_frame</depthOpticalframeName>
        <infrared1OpticalframeName>front_realsense_camera_camera_left_ir_optical_frame</infrared1OpticalframeName>
        <infrared2OpticalframeName>front_realsense_camera_camera_right_ir_optical_frame</infrared2OpticalframeName>
        <rangeMinDepth>0.3</rangeMinDepth>
        <rangeMaxDepth>3.0</rangeMaxDepth>
        <pointCloud>true</pointCloud>
        <pointCloudTopicName>depth/color/points</pointCloudTopicName>
        <pointCloudCutoff>0.3</pointCloudCutoff>
    </plugin> -->

    <plugin name='gazebo_ros_laser_controller' filename='libgazebo_ros_robosense_gpu_laser.so'>
      <ros>
        <namespace>/top_laser</namespace>
        <argument>~/out:=scan</argument>
      </ros>
      <frameName>top_laser_link</frameName>
      <output_type>sensor_msgs/PointCloud2</output_type>
      <min_range>0.4</min_range>
      <max_range>150.0</max_range>
    </plugin>
	
  </model>
</sdf>
