<?xml version="1.0" encoding="utf-8"?>
<sdf version='1.7'>
  <model name='rb_theron'>
    <link name='base_footprint'>
      <inertial>
        <pose>-0.111833 2e-06 0.063888 0 -0 0</pose>
        <mass>51.121</mass>
        <inertia>
          <ixx>2.03814</ixx>
          <ixy>-3.87042e-05</ixy>
          <ixz>-0.0617609</ixz>
          <iyy>2.74275</iyy>
          <iyz>-1.76323e-05</iyz>
          <izz>2.71767</izz>
        </inertia>
      </inertial>
      <collision name='base_footprint_fixed_joint_lump__base_link_collision'>
        <pose>0 0 0.0606 0 -0 0</pose>
        <geometry>
          <mesh>
            <scale>1 1 1</scale>
            <uri>model://rb_theron/meshes/bases/theron_base.stl</uri>
          </mesh>
        </geometry>
        <surface>
          <contact>
            <ode/>
          </contact>
          <friction>
            <ode/>
          </friction>
        </surface>
      </collision>
      <collision name='base_footprint_fixed_joint_lump__robot_bottom_cover_link_collision_1'>
        <pose>0 0 0.0606 0 -0 0</pose>
        <geometry>
          <mesh>
            <scale>1 1 1</scale>
            <uri>model://rb_theron/meshes/bases/mcq_prototype_bottom_cover.dae</uri>
          </mesh>
        </geometry>
      </collision>
      <collision name='base_footprint_fixed_joint_lump__robot_front_laser_base_link_collision_2'>
        <pose>0.25 0 0.2249 3.14159 -7e-06 7e-06</pose>
        <geometry>
          <mesh>
            <scale>1 1 1</scale>
            <uri>model://robotnik_sensors/meshes/sick_nanoscan3.stl</uri>
          </mesh>
        </geometry>
      </collision>
      <collision name='base_footprint_fixed_joint_lump__robot_front_realsense_camera_camera_link_collision_3'>
        <pose>0.318 0 0.2074 0 -0 0</pose>
        <geometry>
          <box>
            <size>0.025 0.1 0.025</size>
          </box>
        </geometry>
        <surface>
          <contact>
            <ode/>
          </contact>
          <friction>
            <ode/>
          </friction>
        </surface>
      </collision>
      <collision name='base_footprint_fixed_joint_lump__robot_front_rgbd_camera_link_collision_4'>
        <pose>0.3305 0 0.2504 0 -0 0</pose>
        <geometry>
          <mesh>
            <scale>1 1 1</scale>
            <uri>model://robotnik_sensors/meshes/orbbec_astra.dae</uri>
          </mesh>
        </geometry>
        <surface>
          <contact>
            <ode/>
          </contact>
          <friction>
            <ode/>
          </friction>
        </surface>
      </collision>
      <!--<collision name='base_footprint_fixed_joint_lump__robot_imu_link_collision_5'>
        <pose>-0.1975 0 0.2204 0 -0 0</pose>
        <geometry>
          <box>
            <size>0.001 0.001 0.001</size>
          </box>
        </geometry>
      </collision> -->
      <visual name='base_footprint_visual'>
        <pose>0 0 0 0 -0 0</pose>
        <geometry>
          <box>
            <size>0.001 0.001 0.001</size>
          </box>
        </geometry>
        <material>
          <script>
            <name>Gazebo/Green</name>
            <uri>file://media/materials/scripts/gazebo.material</uri>
          </script>
        </material>
      </visual>
      <visual name='base_footprint_fixed_joint_lump__base_link_visual_1'>
        <pose>0 0 0.0606 0 -0 0</pose>
        <geometry>
          <mesh>
            <scale>1 1 1</scale>
            <uri>model://rb_theron/meshes/bases/theron_base.stl</uri>
          </mesh>
        </geometry>
        <material>
          <script>
            <name>Gazebo/DarkGrey</name>
            <uri>file://media/materials/scripts/gazebo.material</uri>
          </script>
        </material>
      </visual>
      <visual name='base_footprint_fixed_joint_lump__robot_bottom_cover_link_visual_2'>
        <pose>0 0 0.0606 0 -0 0</pose>
        <geometry>
          <mesh>
            <scale>1 1 1</scale>
            <uri>model://rb_theron/meshes/bases/mcq_prototype_bottom_cover.dae</uri>
          </mesh>
        </geometry>
        <material>
          <script>
            <name>Gazebo/DarkGrey</name>
            <uri>file://media/materials/scripts/gazebo.material</uri>
          </script>
        </material>
      </visual>
      <visual name='base_footprint_fixed_joint_lump__robot_front_laser_base_link_visual_3'>
        <pose>0.25 0 0.2249 3.14159 -7e-06 7e-06</pose>
        <geometry>
          <mesh>
            <scale>1 1 1</scale>
            <uri>model://robotnik_sensors/meshes/sick_nanoscan3.stl</uri>
          </mesh>
        </geometry>
      </visual>
      <visual name='base_footprint_fixed_joint_lump__robot_front_realsense_camera_camera_link_visual_4'>
        <pose>0.3305 0 0.2074 0 -0 0</pose>
        <geometry>
          <mesh>
            <scale>1 1 1</scale>
            <uri>model://robotnik_sensors/meshes/intel_r430.dae</uri>
          </mesh>
        </geometry>
      </visual>
      <visual name='base_footprint_fixed_joint_lump__robot_front_rgbd_camera_link_visual_5'>
        <pose>0.3305 0 0.2504 0 -0 0</pose>
        <geometry>
          <mesh>
            <scale>1 1 1</scale>
            <uri>model://robotnik_sensors/meshes/orbbec_astra.dae</uri>
          </mesh>
        </geometry>
      </visual>
      <visual name='base_footprint_fixed_joint_lump__robot_imu_link_visual_6'>
        <pose>-0.1975 0 0.2204 0 -0 0</pose>
        <geometry>
          <box>
            <size>0.001 0.001 0.001</size>
          </box>
        </geometry>
      </visual>
      <velocity_decay/>
      <velocity_decay/>
      <velocity_decay/>
      <sensor name='robot_front_laser_sensor' type='ray'>
        <visualize>1</visualize>
        <update_rate>12.5</update_rate>
        <ray>
          <scan>
            <horizontal>
              <samples>1618</samples>
              <resolution>1</resolution>
              <min_angle>-2.05076</min_angle>
              <max_angle>2.05076</max_angle>
            </horizontal>
          </scan>
          <range>
            <min>0.065</min>
            <max>40</max>
            <resolution>0.07</resolution>
          </range>
          <noise>
            <type>gaussian</type>
            <mean>0</mean>
            <stddev>0.03</stddev>
          </noise>
        </ray>
        <plugin name='robot_front_laser_controller' filename='libgazebo_ros_ray_sensor.so'>
          <!-- <topicName>front_laser/scan</topicName> -->
		      <ros>
            <remapping>~/out:=scan</remapping>
          </ros>
          <frameName>robot_front_laser_link</frameName>
		      <output_type>sensor_msgs/LaserScan</output_type>
        </plugin>
        <pose>0.25 0 0.1744 0 -7e-06 7e-06</pose>
      </sensor>
      <velocity_decay/>
      <sensor name='robot_front_realsense_camera_depth_sensor' type='depth'>
        <always_on>1</always_on>
        <update_rate>15</update_rate>
        <camera>
          <horizontal_fov>1.59174</horizontal_fov>
          <image>
            <format>R8G8B8</format>
            <width>640</width>
            <height>480</height>
          </image>
          <clip>
            <near>0.3</near>
            <far>10</far>
          </clip>
        </camera>
        <plugin name='robot_front_realsense_camera_controller' filename='libgazebo_ros_openni_kinect.so'>
          <cameraName>front_realsense_camera</cameraName>
          <alwaysOn>1</alwaysOn>
          <updateRate>10</updateRate>
          <imageTopicName>rgb/image_raw</imageTopicName>
          <depthImageTopicName>depth/image_raw</depthImageTopicName>
          <pointCloudTopicName>depth/points</pointCloudTopicName>
          <cameraInfoTopicName>rgb/camera_info</cameraInfoTopicName>
          <depthImageCameraInfoTopicName>depth/camera_info</depthImageCameraInfoTopicName>
          <frameName>/robot_front_realsense_camera_camera_depth_optical_frame</frameName>
          <baseline>0.1</baseline>
          <distortion_k1>0.0</distortion_k1>
          <distortion_k2>0.0</distortion_k2>
          <distortion_k3>0.0</distortion_k3>
          <distortion_t1>0.0</distortion_t1>
          <distortion_t2>0.0</distortion_t2>
          <pointCloudCutoff>0.4</pointCloudCutoff>
        </plugin>
        <pose>0.3305 0 0.2074 0 -0 0</pose>
      </sensor>
      <gravity>1</gravity>
      <velocity_decay/>
      <sensor name='robot_front_rgbd_camera_depth_sensor' type='depth'>
        <always_on>1</always_on>
        <update_rate>20</update_rate>
        <camera>
          <horizontal_fov>1.0472</horizontal_fov>
          <image>
            <format>R8G8B8</format>
            <width>640</width>
            <height>480</height>
          </image>
          <clip>
            <near>0.05</near>
            <far>3.5</far>
          </clip>
        </camera>
        <plugin name='robot_front_rgbd_camera_controller' filename='libgazebo_ros_openni_kinect.so'>
          <cameraName>front_rgbd_camera</cameraName>
          <alwaysOn>1</alwaysOn>
          <updateRate>10</updateRate>
          <imageTopicName>rgb/image_raw</imageTopicName>
          <depthImageTopicName>depth/image_raw</depthImageTopicName>
          <pointCloudTopicName>depth/points</pointCloudTopicName>
          <cameraInfoTopicName>rgb/camera_info</cameraInfoTopicName>
          <depthImageCameraInfoTopicName>depth/camera_info</depthImageCameraInfoTopicName>
          <frameName>/robot_front_rgbd_camera_depth_optical_frame</frameName>
          <baseline>0.1</baseline>
          <distortion_k1>0.0</distortion_k1>
          <distortion_k2>0.0</distortion_k2>
          <distortion_k3>0.0</distortion_k3>
          <distortion_t1>0.0</distortion_t1>
          <distortion_t2>0.0</distortion_t2>
          <pointCloudCutoff>0.4</pointCloudCutoff>
        </plugin>
        <pose>0.3305 0 0.2504 0 -0 0</pose>
      </sensor>
    </link>
    <joint name='robot_leftjoint_rsupport' type='revolute'>
      <pose relative_to='base_footprint'>0.1175 0.1725 0.1034 0 -0 0</pose>
      <parent>base_footprint</parent>
      <child>robot_leftrsupport</child>
      <axis>
        <xyz>0 1 0</xyz>
        <limit>
          <lower>-0.5</lower>
          <upper>0.5</upper>
          <effort>100</effort>
          <velocity>100</velocity>
        </limit>
        <dynamics>
          <spring_reference>0</spring_reference>
          <spring_stiffness>0</spring_stiffness>
        </dynamics>
      </axis>
    </joint>
    <link name='robot_leftrsupport'>
      <pose relative_to='robot_leftjoint_rsupport'>0 0 0 0 -0 0</pose>
      <inertial>
        <pose>0 0 0 0 -0 0</pose>
        <mass>1.5</mass>
        <inertia>
          <ixx>5e-05</ixx>
          <ixy>0</ixy>
          <ixz>0</ixz>
          <iyy>5e-05</iyy>
          <iyz>0</iyz>
          <izz>7.5e-05</izz>
        </inertia>
      </inertial>
      <collision name='robot_leftrsupport_collision'>
        <pose>0 0 0 0 -0 0</pose>
        <geometry>
          <mesh>
            <scale>1 1 1</scale>
            <uri>model://rb_theron/meshes/rocker/mcq_prototype_rocker_l.dae</uri>
          </mesh>
        </geometry>
      </collision>
      <visual name='robot_leftrsupport_visual'>
        <pose>0 0 0 0 -0 0</pose>
        <geometry>
          <mesh>
            <scale>1 1 1</scale>
            <uri>model://rb_theron/meshes/rocker/mcq_prototype_rocker_l.dae</uri>
          </mesh>
        </geometry>
      </visual>
    </link>
    <joint name='robot_left_wheel_joint' type='revolute'>
      <pose relative_to='robot_leftrsupport'>-0.1175 0.079 -0.0428 0 -0 0</pose>
      <parent>robot_leftrsupport</parent>
      <child>robot_left_wheel_link</child>
      <axis>
        <xyz>0 1 0</xyz>
        <limit>
          <lower>-1e+16</lower>
          <upper>1e+16</upper>
        </limit>
        <dynamics>
          <spring_reference>0</spring_reference>
          <spring_stiffness>0</spring_stiffness>
        </dynamics>
      </axis>
    </joint>
    <link name='robot_left_wheel_link'>
      <pose relative_to='robot_left_wheel_joint'>0 0 0 0 -0 0</pose>
      <inertial>
        <pose>0 0 0 0 -0 0</pose>
        <mass>0.25</mass>
        <inertia>
          <ixx>0.000370231</ixx>
          <ixy>0</ixy>
          <ixz>0</ixz>
          <iyy>0.000370231</iyy>
          <iyz>0</iyz>
          <izz>0.00071442</izz>
        </inertia>
      </inertial>
      <collision name='robot_left_wheel_link_collision'>
        <pose>0 0 0 1.5708 -0 0</pose>
        <geometry>
          <cylinder>
            <length>0.025</length>
            <radius>0.0756</radius>
          </cylinder>
        </geometry>
        <surface>
          <contact>
            <ode>
              <kp>500000</kp>
              <kd>1</kd>
            </ode>
          </contact>
          <friction>
            <ode>
              <mu>100</mu>
              <mu2>100</mu2>
            </ode>
          </friction>
        </surface>
      </collision>
      <visual name='robot_left_wheel_link_visual'>
        <pose>0 0 0 1.5708 -0 0</pose>
        <geometry>
          <cylinder>
            <length>0.025</length>
            <radius>0.0756</radius>
          </cylinder>
        </geometry>
        <material>
          <script>
            <name>Gazebo/Yellow</name>
            <uri>file://media/materials/scripts/gazebo.material</uri>
          </script>
        </material>
      </visual>
      <gravity>1</gravity>
      <velocity_decay/>
    </link>
    <joint name='robot_leftcastorjoint_support' type='revolute'>
      <pose relative_to='robot_leftrsupport'>0.1175 0.01 0.002 0 -0 0</pose>
      <parent>robot_leftrsupport</parent>
      <child>robot_leftcastorsupport</child>
      <axis>
        <xyz>0 0 1</xyz>
        <limit>
          <lower>-1e+16</lower>
          <upper>1e+16</upper>
        </limit>
        <dynamics>
          <damping>0</damping>
          <friction>0.01</friction>
          <spring_reference>0</spring_reference>
          <spring_stiffness>0</spring_stiffness>
        </dynamics>
      </axis>
    </joint>
    <link name='robot_leftcastorsupport'>
      <pose relative_to='robot_leftcastorjoint_support'>0 0 0 0 -0 0</pose>
      <inertial>
        <pose>0 0 0 0 -0 0</pose>
        <mass>1.5</mass>
        <inertia>
          <ixx>5e-05</ixx>
          <ixy>0</ixy>
          <ixz>0</ixz>
          <iyy>5e-05</iyy>
          <iyz>0</iyz>
          <izz>7.5e-05</izz>
        </inertia>
      </inertial>
      <collision name='robot_leftcastorsupport_collision'>
        <pose>0 0 0 0 -0 0</pose>
        <geometry>
          <mesh>
            <scale>1 1 1</scale>
            <uri>model://rb_theron/meshes/wheels/mcq_prototype_base_castor.dae</uri>
          </mesh>
        </geometry>
      </collision>
      <visual name='robot_leftcastorsupport_visual'>
        <pose>0 0 0 0 -0 0</pose>
        <geometry>
          <mesh>
            <scale>1 1 1</scale>
            <uri>model://rb_theron/meshes/wheels/mcq_prototype_base_castor.dae</uri>
          </mesh>
        </geometry>
      </visual>
    </link>
    <joint name='robot_leftcastorjoint_wheel' type='revolute'>
      <pose relative_to='robot_leftcastorsupport'>-0.033 0 -0.071 0 -0 0</pose>
      <parent>robot_leftcastorsupport</parent>
      <child>robot_leftcastorwheel</child>
      <axis>
        <xyz>0 1 0</xyz>
        <limit>
          <lower>-1e+16</lower>
          <upper>1e+16</upper>
        </limit>
        <dynamics>
          <spring_reference>0</spring_reference>
          <spring_stiffness>0</spring_stiffness>
        </dynamics>
      </axis>
    </joint>
    <link name='robot_leftcastorwheel'>
      <pose relative_to='robot_leftcastorjoint_wheel'>0 0 0 0 -0 0</pose>
      <inertial>
        <pose>0 0 0 0 -0 0</pose>
        <mass>0.25</mass>
        <inertia>
          <ixx>0.000169271</ixx>
          <ixy>0</ixy>
          <ixz>0</ixz>
          <iyy>0.000169271</iyy>
          <iyz>0</iyz>
          <izz>0.0003125</izz>
        </inertia>
      </inertial>
      <collision name='robot_leftcastorwheel_collision'>
        <pose>0 0 0 1.5708 -0 0</pose>
        <geometry>
          <cylinder>
            <length>0.025</length>
            <radius>0.05</radius>
          </cylinder>
        </geometry>
      </collision>
      <visual name='robot_leftcastorwheel_visual'>
        <pose>0 0 0 1.5708 -0 0</pose>
        <geometry>
          <cylinder>
            <length>0.025</length>
            <radius>0.05</radius>
          </cylinder>
        </geometry>
      </visual>
    </link>
    <joint name='robot_leftjoint_support' type='revolute'>
      <pose relative_to='base_footprint'>-0.235 0.1725 0.1034 0 -0 0</pose>
      <parent>base_footprint</parent>
      <child>robot_leftsupport</child>
      <axis>
        <xyz>0 0 1</xyz>
        <limit>
          <lower>-1e+16</lower>
          <upper>1e+16</upper>
        </limit>
        <dynamics>
          <damping>0</damping>
          <friction>0.01</friction>
          <spring_reference>0</spring_reference>
          <spring_stiffness>0</spring_stiffness>
        </dynamics>
      </axis>
    </joint>
    <link name='robot_leftsupport'>
      <pose relative_to='robot_leftjoint_support'>0 0 0 0 -0 0</pose>
      <inertial>
        <pose>0 0 0 0 -0 0</pose>
        <mass>1.5</mass>
        <inertia>
          <ixx>5e-05</ixx>
          <ixy>0</ixy>
          <ixz>0</ixz>
          <iyy>5e-05</iyy>
          <iyz>0</iyz>
          <izz>7.5e-05</izz>
        </inertia>
      </inertial>
      <collision name='robot_leftsupport_collision'>
        <pose>0 0 0 0 -0 0</pose>
        <geometry>
          <mesh>
            <scale>1 1 1</scale>
            <uri>model://rb_theron/meshes/wheels/mcq_prototype_base_castor.dae</uri>
          </mesh>
        </geometry>
      </collision>
      <visual name='robot_leftsupport_visual'>
        <pose>0 0 0 0 -0 0</pose>
        <geometry>
          <mesh>
            <scale>1 1 1</scale>
            <uri>model://rb_theron/meshes/wheels/mcq_prototype_base_castor.dae</uri>
          </mesh>
        </geometry>
      </visual>
    </link>
    <joint name='robot_leftjoint_wheel' type='revolute'>
      <pose relative_to='robot_leftsupport'>-0.033 0 -0.071 0 -0 0</pose>
      <parent>robot_leftsupport</parent>
      <child>robot_leftwheel</child>
      <axis>
        <xyz>0 1 0</xyz>
        <limit>
          <lower>-1e+16</lower>
          <upper>1e+16</upper>
        </limit>
        <dynamics>
          <spring_reference>0</spring_reference>
          <spring_stiffness>0</spring_stiffness>
        </dynamics>
      </axis>
    </joint>
    <link name='robot_leftwheel'>
      <pose relative_to='robot_leftjoint_wheel'>0 0 0 0 -0 0</pose>
      <inertial>
        <pose>0 0 0 0 -0 0</pose>
        <mass>0.25</mass>
        <inertia>
          <ixx>0.000169271</ixx>
          <ixy>0</ixy>
          <ixz>0</ixz>
          <iyy>0.000169271</iyy>
          <iyz>0</iyz>
          <izz>0.0003125</izz>
        </inertia>
      </inertial>
      <collision name='robot_leftwheel_collision'>
        <pose>0 0 0 1.5708 -0 0</pose>
        <geometry>
          <cylinder>
            <length>0.025</length>
            <radius>0.05</radius>
          </cylinder>
        </geometry>
      </collision>
      <visual name='robot_leftwheel_visual'>
        <pose>0 0 0 1.5708 -0 0</pose>
        <geometry>
          <cylinder>
            <length>0.025</length>
            <radius>0.05</radius>
          </cylinder>
        </geometry>
      </visual>
    </link>
    <joint name='robot_rightjoint_rsupport' type='revolute'>
      <pose relative_to='base_footprint'>0.1175 -0.1725 0.1034 0 -0 0</pose>
      <parent>base_footprint</parent>
      <child>robot_rightrsupport</child>
      <axis>
        <xyz>0 1 0</xyz>
        <limit>
          <lower>-0.5</lower>
          <upper>0.5</upper>
          <effort>100</effort>
          <velocity>100</velocity>
        </limit>
        <dynamics>
          <spring_reference>0</spring_reference>
          <spring_stiffness>0</spring_stiffness>
        </dynamics>
      </axis>
    </joint>
    <link name='robot_rightrsupport'>
      <pose relative_to='robot_rightjoint_rsupport'>0 0 0 0 -0 0</pose>
      <inertial>
        <pose>0 0 0 0 -0 0</pose>
        <mass>1.5</mass>
        <inertia>
          <ixx>5e-05</ixx>
          <ixy>0</ixy>
          <ixz>0</ixz>
          <iyy>5e-05</iyy>
          <iyz>0</iyz>
          <izz>7.5e-05</izz>
        </inertia>
      </inertial>
      <collision name='robot_rightrsupport_collision'>
        <pose>0 0 0 0 -0 0</pose>
        <geometry>
          <mesh>
            <scale>1 1 1</scale>
            <uri>model://rb_theron/meshes/rocker/mcq_prototype_rocker_r.dae</uri>
          </mesh>
        </geometry>
      </collision>
      <visual name='robot_rightrsupport_visual'>
        <pose>0 0 0 0 -0 0</pose>
        <geometry>
          <mesh>
            <scale>1 1 1</scale>
            <uri>model://rb_theron/meshes/rocker/mcq_prototype_rocker_r.dae</uri>
          </mesh>
        </geometry>
      </visual>
    </link>
    <joint name='robot_right_wheel_joint' type='revolute'>
      <pose relative_to='robot_rightrsupport'>-0.1175 -0.079 -0.0428 0 -0 0</pose>
      <parent>robot_rightrsupport</parent>
      <child>robot_right_wheel_link</child>
      <axis>
        <xyz>0 1 0</xyz>
        <limit>
          <lower>-1e+16</lower>
          <upper>1e+16</upper>
        </limit>
        <dynamics>
          <spring_reference>0</spring_reference>
          <spring_stiffness>0</spring_stiffness>
        </dynamics>
      </axis>
    </joint>
    <link name='robot_right_wheel_link'>
      <pose relative_to='robot_right_wheel_joint'>0 0 0 0 -0 0</pose>
      <inertial>
        <pose>0 0 0 0 -0 0</pose>
        <mass>0.25</mass>
        <inertia>
          <ixx>0.000370231</ixx>
          <ixy>0</ixy>
          <ixz>0</ixz>
          <iyy>0.000370231</iyy>
          <iyz>0</iyz>
          <izz>0.00071442</izz>
        </inertia>
      </inertial>
      <collision name='robot_right_wheel_link_collision'>
        <pose>0 0 0 1.5708 -0 0</pose>
        <geometry>
          <cylinder>
            <length>0.025</length>
            <radius>0.0756</radius>
          </cylinder>
        </geometry>
        <surface>
          <contact>
            <ode>
              <kp>500000</kp>
              <kd>1</kd>
            </ode>
          </contact>
          <friction>
            <ode>
              <mu>100</mu>
              <mu2>100</mu2>
            </ode>
          </friction>
        </surface>
      </collision>
      <visual name='robot_right_wheel_link_visual'>
        <pose>0 0 0 1.5708 -0 0</pose>
        <geometry>
          <cylinder>
            <length>0.025</length>
            <radius>0.0756</radius>
          </cylinder>
        </geometry>
        <material>
          <script>
            <name>Gazebo/Yellow</name>
            <uri>file://media/materials/scripts/gazebo.material</uri>
          </script>
        </material>
      </visual>
      <gravity>1</gravity>
      <velocity_decay/>
    </link>
    <joint name='robot_rightcastorjoint_support' type='revolute'>
      <pose relative_to='robot_rightrsupport'>0.1175 0.01 0.002 0 -0 0</pose>
      <parent>robot_rightrsupport</parent>
      <child>robot_rightcastorsupport</child>
      <axis>
        <xyz>0 0 1</xyz>
        <limit>
          <lower>-1e+16</lower>
          <upper>1e+16</upper>
        </limit>
        <dynamics>
          <damping>0</damping>
          <friction>0.01</friction>
          <spring_reference>0</spring_reference>
          <spring_stiffness>0</spring_stiffness>
        </dynamics>
      </axis>
    </joint>
    <link name='robot_rightcastorsupport'>
      <pose relative_to='robot_rightcastorjoint_support'>0 0 0 0 -0 0</pose>
      <inertial>
        <pose>0 0 0 0 -0 0</pose>
        <mass>1.5</mass>
        <inertia>
          <ixx>5e-05</ixx>
          <ixy>0</ixy>
          <ixz>0</ixz>
          <iyy>5e-05</iyy>
          <iyz>0</iyz>
          <izz>7.5e-05</izz>
        </inertia>
      </inertial>
      <collision name='robot_rightcastorsupport_collision'>
        <pose>0 0 0 0 -0 0</pose>
        <geometry>
          <mesh>
            <scale>1 1 1</scale>
            <uri>model://rb_theron/meshes/wheels/mcq_prototype_base_castor.dae</uri>
          </mesh>
        </geometry>
      </collision>
      <visual name='robot_rightcastorsupport_visual'>
        <pose>0 0 0 0 -0 0</pose>
        <geometry>
          <mesh>
            <scale>1 1 1</scale>
            <uri>model://rb_theron/meshes/wheels/mcq_prototype_base_castor.dae</uri>
          </mesh>
        </geometry>
      </visual>
    </link>
    <joint name='robot_rightcastorjoint_wheel' type='revolute'>
      <pose relative_to='robot_rightcastorsupport'>-0.033 0 -0.071 0 -0 0</pose>
      <parent>robot_rightcastorsupport</parent>
      <child>robot_rightcastorwheel</child>
      <axis>
        <xyz>0 1 0</xyz>
        <limit>
          <lower>-1e+16</lower>
          <upper>1e+16</upper>
        </limit>
        <dynamics>
          <spring_reference>0</spring_reference>
          <spring_stiffness>0</spring_stiffness>
        </dynamics>
      </axis>
    </joint>
    <link name='robot_rightcastorwheel'>
      <pose relative_to='robot_rightcastorjoint_wheel'>0 0 0 0 -0 0</pose>
      <inertial>
        <pose>0 0 0 0 -0 0</pose>
        <mass>0.25</mass>
        <inertia>
          <ixx>0.000169271</ixx>
          <ixy>0</ixy>
          <ixz>0</ixz>
          <iyy>0.000169271</iyy>
          <iyz>0</iyz>
          <izz>0.0003125</izz>
        </inertia>
      </inertial>
      <collision name='robot_rightcastorwheel_collision'>
        <pose>0 0 0 1.5708 -0 0</pose>
        <geometry>
          <cylinder>
            <length>0.025</length>
            <radius>0.05</radius>
          </cylinder>
        </geometry>
      </collision>
      <visual name='robot_rightcastorwheel_visual'>
        <pose>0 0 0 1.5708 -0 0</pose>
        <geometry>
          <cylinder>
            <length>0.025</length>
            <radius>0.05</radius>
          </cylinder>
        </geometry>
      </visual>
    </link>
    <joint name='robot_rightjoint_support' type='revolute'>
      <pose relative_to='base_footprint'>-0.235 -0.1725 0.1034 0 -0 0</pose>
      <parent>base_footprint</parent>
      <child>robot_rightsupport</child>
      <axis>
        <xyz>0 0 1</xyz>
        <limit>
          <lower>-1e+16</lower>
          <upper>1e+16</upper>
        </limit>
        <dynamics>
          <damping>0</damping>
          <friction>0.01</friction>
          <spring_reference>0</spring_reference>
          <spring_stiffness>0</spring_stiffness>
        </dynamics>
      </axis>
    </joint>
    <link name='robot_rightsupport'>
      <pose relative_to='robot_rightjoint_support'>0 0 0 0 -0 0</pose>
      <inertial>
        <pose>0 0 0 0 -0 0</pose>
        <mass>1.5</mass>
        <inertia>
          <ixx>5e-05</ixx>
          <ixy>0</ixy>
          <ixz>0</ixz>
          <iyy>5e-05</iyy>
          <iyz>0</iyz>
          <izz>7.5e-05</izz>
        </inertia>
      </inertial>
      <collision name='robot_rightsupport_collision'>
        <pose>0 0 0 0 -0 0</pose>
        <geometry>
          <mesh>
            <scale>1 1 1</scale>
            <uri>model://rb_theron/meshes/wheels/mcq_prototype_base_castor.dae</uri>
          </mesh>
        </geometry>
      </collision>
      <visual name='robot_rightsupport_visual'>
        <pose>0 0 0 0 -0 0</pose>
        <geometry>
          <mesh>
            <scale>1 1 1</scale>
            <uri>model://rb_theron/meshes/wheels/mcq_prototype_base_castor.dae</uri>
          </mesh>
        </geometry>
      </visual>
    </link>
    <joint name='robot_rightjoint_wheel' type='revolute'>
      <pose relative_to='robot_rightsupport'>-0.033 0 -0.071 0 -0 0</pose>
      <parent>robot_rightsupport</parent>
      <child>robot_rightwheel</child>
      <axis>
        <xyz>0 1 0</xyz>
        <limit>
          <lower>-1e+16</lower>
          <upper>1e+16</upper>
        </limit>
        <dynamics>
          <spring_reference>0</spring_reference>
          <spring_stiffness>0</spring_stiffness>
        </dynamics>
      </axis>
    </joint>
    <link name='robot_rightwheel'>
      <pose relative_to='robot_rightjoint_wheel'>0 0 0 0 -0 0</pose>
      <inertial>
        <pose>0 0 0 0 -0 0</pose>
        <mass>0.25</mass>
        <inertia>
          <ixx>0.000169271</ixx>
          <ixy>0</ixy>
          <ixz>0</ixz>
          <iyy>0.000169271</iyy>
          <iyz>0</iyz>
          <izz>0.0003125</izz>
        </inertia>
      </inertial>
      <collision name='robot_rightwheel_collision'>
        <pose>0 0 0 1.5708 -0 0</pose>
        <geometry>
          <cylinder>
            <length>0.025</length>
            <radius>0.05</radius>
          </cylinder>
        </geometry>
      </collision>
      <visual name='robot_rightwheel_visual'>
        <pose>0 0 0 1.5708 -0 0</pose>
        <geometry>
          <cylinder>
            <length>0.025</length>
            <radius>0.05</radius>
          </cylinder>
        </geometry>
      </visual>
    </link>
	<joint name="imu_joint" type="fixed">
      <parent>base_footprint</parent>
      <child>imu_link</child>
      <pose>-0.1975 0 0.2204 0 -0 0</pose>
      <axis>
        <xyz>0 0 1</xyz>
      </axis>
    </joint>    	
	<link name="imu_link">
      <sensor name="theron_imu" type="imu">
        <always_on>true</always_on>
        <update_rate>200</update_rate>
        <imu>
          <angular_velocity>
            <x>
              <noise type="gaussian">
                <mean>0.0</mean>
                <stddev>2e-4</stddev>
              </noise>
            </x>
            <y>
              <noise type="gaussian">
                <mean>0.0</mean>
                <stddev>2e-4</stddev>
              </noise>
            </y>
            <z>
              <noise type="gaussian">
                <mean>0.0</mean>
                <stddev>2e-4</stddev>
              </noise>
            </z>
          </angular_velocity>
          <linear_acceleration>
            <x>
              <noise type="gaussian">
                <mean>0.0</mean>
                <stddev>1.7e-2</stddev>
              </noise>
            </x>
            <y>
              <noise type="gaussian">
                <mean>0.0</mean>
                <stddev>1.7e-2</stddev>
              </noise>
            </y>
            <z>
              <noise type="gaussian">
                <mean>0.0</mean>
                <stddev>1.7e-2</stddev>
              </noise>
            </z>
          </linear_acceleration>
        </imu>
        <plugin name="robot_imu" filename="libgazebo_ros_imu_sensor.so">
          <ros>
            <!-- <namespace>/tb3</namespace> -->
            <remapping>~/out:=imu</remapping>
          </ros>
        </plugin>
      </sensor>
    </link>	
	
    <plugin name='ros_control' filename='libgazebo_ros_control.so'>
      <robotParam>robot/robot_description</robotParam>
      <controlPeriod>0.001</controlPeriod>
      <robotSimType>gazebo_ros_control/DefaultRobotHWSim</robotSimType>
      <legacyModeNS>1</legacyModeNS>
    </plugin>
	
    <static>0</static>
    
    <plugin name="robot_diff_drive" filename="libgazebo_ros_diff_drive.so">
      <alwaysOn>1</alwaysOn>
	
	  <ros>
        <!-- <namespace>/tb3</namespace> -->
      </ros>

      <update_rate>30</update_rate>

      <!-- wheels -->
      <left_joint>robot_left_wheel_joint</left_joint>
      <right_joint>robot_right_wheel_joint</right_joint>

      <!-- kinematics -->
      <wheel_separation>0.287</wheel_separation>
      <wheel_diameter>0.158</wheel_diameter>

      <!-- limits -->
      <max_wheel_torque>20</max_wheel_torque>
      <max_wheel_acceleration>1.0</max_wheel_acceleration>

      <command_topic>cmd_vel</command_topic>

      <!-- output -->
      <publish_odom>true</publish_odom>
      <publish_odom_tf>true</publish_odom_tf>
      <publish_wheel_tf>false</publish_wheel_tf>

      <odometry_topic>odom</odometry_topic>
      <odometry_frame>odom</odometry_frame>
      <robot_base_frame>base_footprint</robot_base_frame>
    </plugin>
	
	 <plugin name="robot_joint_state" filename="libgazebo_ros_joint_state_publisher.so">
      <ros>
        <!-- <namespace>/tb3</namespace> -->
        <remapping>~/out:=joint_states</remapping>
      </ros>
	  <alwaysOn>1</alwaysOn>
      <update_rate>30</update_rate>
      <joint_name>robot_left_wheel_joint</joint_name>
      <joint_name>robot_right_wheel_joint</joint_name>
    </plugin>    
	
  </model>
</sdf>
