<?xml version="1.0" encoding="utf-8"?>
<!-- =================================================================================== -->
<!-- |    This document was autogenerated by xacro from rb_theron.urdf.xacro           | -->
<!-- |    EDITING THIS FILE BY HAND IS NOT RECOMMENDED                                 | -->
<!-- =================================================================================== -->
<robot name="rb_theron">
  <!-- ***************** -->
  <!-- Imported elements -->
  <!-- ***************** -->
  <!-- First we import all posible elements defined in the urdf.xacro files. All these elements are defined as macro:xacros -->
  <!-- in kg-->
  <!-- in kg-->
  <!-- in kg-->
  <!-- in kg-->
  <!-- in kg-->
  <!-- in kg-->
  <!-- in kg-->
  <!-- source en.wikipedia.org/wiki/List_of_moments_of_inertia-->
  <!-- This file unifies all sensors that can be used on simulation, defined as xacro:macros -->
  <!-- Includes -->
  <!-- *************** -->
  <!-- Robots Elements -->
  <!-- *************** -->
  <!-- Here we create the robot elements using the xacro:macros imported at the beggining of this file -->
  <!-- this property is for the chassis -->
  <!-- xacro:property name="wheel_width" value="0.150" / -->
  <link name="base_footprint">
    <visual>
      <origin rpy="0 0 0" xyz="0 0 0"/>
      <geometry>
        <box size="0.001 0.001 0.001"/>
      </geometry>
    </visual>
  </link>
  <joint name="base_footprint_joint" type="fixed">
    <origin rpy="0 0 0" xyz="0 0 0.0606"/>
    <parent link="base_footprint"/>
    <child link="base_link"/>
  </joint>
  <!-- BASE_LINK -->
  <link name="base_link">
    <inertial>
      <mass value="50.0"/>
      <origin xyz="-0.120 0 0"/>
      <inertia ixx="2.01041666667" ixy="0" ixz="0" iyy="2.55208333333" iyz="0" izz="2.55208333333"/>
    </inertial>
    <visual>
      <origin rpy="0 0 0" xyz="0 0 0"/>
      <geometry>
        <mesh filename="meshes/bases/theron_base.stl"/>
      </geometry>
      <material name="darkgrey">
        <color rgba="0.1 0.1 0.1 1"/>
      </material>
    </visual>
    <collision>
      <origin rpy="0 0 0 " xyz="0 0 0"/>
      <geometry>
        <!--box size="0.390 0.240 0.165"/-->
        <mesh filename="meshes/bases/theron_base.stl"/>
      </geometry>
    </collision>
  </link>
  <link name="bottom_cover_link">
    <inertial>
      <mass value="2.0"/>
      <origin xyz="0 0 0"/>
      <inertia ixx="0.0804166666667" ixy="0" ixz="0" iyy="0.102083333333" iyz="0" izz="0.102083333333"/>
    </inertial>
    <visual>
      <origin rpy="0 0 0" xyz="0 0 0"/>
      <geometry>
        <mesh filename="meshes/bases/mcq_prototype_bottom_cover.dae"/>
      </geometry>
      <material name="darkgrey">
        <color rgba="0.1 0.1 0.1 1"/>
      </material>
    </visual>
    <collision>
      <origin rpy="0 0 0 " xyz="0 0 0"/>
      <geometry>
        <mesh filename="meshes/bases/mcq_prototype_bottom_cover.dae"/>
      </geometry>
    </collision>
  </link>
  <joint name="bottom_cover_joint" type="fixed">
    <origin rpy="0 0 0" xyz="0 0 0"/>
    <parent link="base_link"/>
    <child link="bottom_cover_link"/>
  </joint>
  <!-- DOCKING CONTACTS -->
  <!--joint name="${prefix}base_docking_joint" type="fixed">
      <origin xyz="0.030 0.000 0.068" rpy="0 0 0 " />
      <parent link="${prefix}front_cover_link"/>
      <child link="${prefix}base_docking_contact_link" />
    </joint-->
  <!-- DOCKING LINK -->
  <!--link name="${prefix}base_docking_contact_link" /-->
  <gazebo>
    <plugin filename="libgazebo_ros_control.so" name="ros_control">
      <!--robotNamespace>/robot</robotNamespace-->
      <robotParam>robot/description</robotParam>
      <controlPeriod>0.001</controlPeriod>
      <robotSimType>gazebo_ros_control/DefaultRobotHWSim</robotSimType>
      <legacyModeNS>true</legacyModeNS>
    </plugin>
  </gazebo>
  <gazebo reference="base_footprint">
    <material>Gazebo/Green</material>
  </gazebo>
  <gazebo reference="base_link">
    <material>Gazebo/Grey</material>
  </gazebo>
  <gazebo reference="front_cover_link">
    <material>Gazebo/Black</material>
  </gazebo>
  <!--ROCKER BOGIE SUPPORT -->
  <!--joint name="${prefix}joint_support" type="continuous">
      <parent link="${parent}"/>
      <child link="${prefix}support"/>
      <insert_block name="origin" />
      <axis xyz="0 1 0" rpy="0 0 ${M_PI}" />
      <limit effort="100" velocity="100"/>
      <joint_properties damping="0.1" friction="0.1"/>
	</joint -->
  <joint name="rightjoint_rsupport" type="revolute">
    <parent link="base_link"/>
    <child link="rightrsupport"/>
    <origin rpy="0 0 0" xyz="0.1175 -0.1725 0.0428"/>
    <axis rpy="0 0 3.14159265359" xyz="0 1 0"/>
    <limit effort="100" lower="-0.5" upper="0.5" velocity="100"/>
    <joint_properties damping="0.1" friction="0.1"/>
  </joint>
  <link name="rightrsupport">
    <visual>
      <origin rpy="0 0 0" xyz="0 0 0"/>
      <geometry>
        <mesh filename="meshes/rocker/mcq_prototype_rocker_r.dae"/>
      </geometry>
    </visual>
    <collision>
      <origin rpy="0 0 0" xyz="0 0 0"/>
      <geometry>
        <mesh filename="meshes/rocker/mcq_prototype_rocker_r.dae"/>
      </geometry>
    </collision>
    <inertial>
      <mass value="1.5"/>
      <origin xyz="0 0 0"/>
      <inertia ixx="5e-05" ixy="0" ixz="0" iyy="5e-05" iyz="0" izz="7.5e-05"/>
      <!--Check these values -->
    </inertial>
  </link>
  <!-- Transmission is important to link the joints and the controller -->
  <transmission name="rightrsupport_joint_trans">
    <type>transmission_interface/SimpleTransmission</type>
    <joint name="rightjoint_rsupport">
      <hardwareInterface>hardware_interface/EffortJointInterface</hardwareInterface>
    </joint>
    <actuator name="rightrsupport_joint_motor">
      <mechanicalReduction>1</mechanicalReduction>
      <motorTorqueConstant>1</motorTorqueConstant>
    </actuator>
  </transmission>
  <!-- xacro:rubber_wheel prefix="$(arg prefix)wheel" parent="$(arg prefix)support" reflect="true" hq="${hq}">
		<origin xyz="${wheel_offset_x} ${wheel_offset_y} ${wheel_offset_z}" rpy="0 0 0"/>
	</xacro:rubber_wheel -->
  <!--WHEEL TIRE -->
  <joint name="right_wheel_joint" type="continuous">
    <parent link="rightrsupport"/>
    <child link="right_wheel_link"/>
    <origin rpy="0 0 0" xyz="-0.1175 -0.079 -0.0428"/>
    <axis rpy="0 0 0" xyz="0 1 0"/>
    <limit effort="100" velocity="100"/>
    <joint_properties damping="0.0" friction="0.0"/>
  </joint>
  <link name="right_wheel_link">
    <visual>
      <!-- HIGH RESOLUTION WHEELS -->
      <!-- LOW RESOLUTION WHEELS -->
      <origin rpy="1.57079632679 0 0" xyz="0 0 0"/>
      <geometry>
        <cylinder length="0.025" radius="0.0756"/>
      </geometry>
    </visual>
    <collision>
      <origin rpy="1.57079632679 0 0" xyz="0 0 0"/>
      <geometry>
        <cylinder length="0.025" radius="0.0756"/>
      </geometry>
    </collision>
    <inertial>
      <mass value="0.25"/>
      <origin xyz="0 0 0"/>
      <inertia ixx="0.000370230833333" ixy="0" ixz="0" iyy="0.000370230833333" iyz="0" izz="0.00071442"/>
    </inertial>
  </link>
  <!-- Transmission is important to link the joints and the controller (see rb_theron_control/config/rb_theron_control.yaml)-->
  <transmission name="right_wheel_joint_trans">
    <type>transmission_interface/SimpleTransmission</type>
    <joint name="right_wheel_joint">
      <!-- for the gazebo plugin -->
      <!--hardwareInterface>EffortJointInterface</hardwareInterface-->
      <!-- for ros control controller -->
      <hardwareInterface>hardware_interface/VelocityJointInterface</hardwareInterface>
    </joint>
    <actuator name="right_wheel_joint_motor">
      <mechanicalReduction>1</mechanicalReduction>
      <motorTorqueConstant>20</motorTorqueConstant>
    </actuator>
  </transmission>
  <gazebo reference="right_wheel_link">
    <!-- mu1 value="5.0"/>
			<mu2 value="0.5"/>
			<kp value="10000000.0" />
			<kd value="1.0" />
			<fdir1 value="1 0 0"/>
			<material>Gazebo/Yellow</material>
			<turnGravityOff>false</turnGravityOff -->
    <!-- mu1 value="5.0"/>
			<mu2 value="0.5"/ -->
    <mu1 value="100.0"/>
    <mu2 value="100.0"/>
    <!-- kp value="100000.0" / -->
    <kp value="500000.0"/>
    <kd value="1.0"/>
    <!-- fdir1 value="1 0 0"/ -->
    <material>Gazebo/Yellow</material>
    <turnGravityOff>false</turnGravityOff>
    <!--kp>500000.0</kp>
			<kd>10.0</kd>
			<mu1>10</mu1>
			<mu2>10</mu2>
			<fdir1>1 0 0</fdir1-->
    <!--minDepth>0.001</minDepth-->
    <!--material>Gazebo/Black</material-->
    <!--mu1 value="10"/>
			<mu2 value="5"/>
			<kp value="500000.0" />
			<kd value="10.0" />
			<fdir1 value="1 0 0"/>
			<material>Gazebo/Yellow</material>
			<turnGravityOff>false</turnGravityOff-->
  </gazebo>
  <!--gazebo reference="${name}_wheel_link">
			<kp>500000.0</kp>
			<kd>10.0</kd>
			<mu1>10</mu1>
			<mu2>10</mu2>
			<fdir1>1 0 0</fdir1>
			<maxVel>1.0</maxVel>
			<minDepth>0.003</minDepth>
			<material>Gazebo/Yellow</material>
			<turnGravityOff>false</turnGravityOff>
			<implicitSpringDamper>1</implicitSpringDamper>
		</gazebo-->
  <!-- xacro:caster prefix="$(arg prefix)left" parent="$(arg prefix)support" hq="${hq}">
		<origin xyz="${caster_offset_x} ${caster_offset_y} ${caster_offset_z}" rpy="0 0 0"/>
	</xacro:caster -->
  <!--CASTER SUPPORT -->
  <joint name="rightcastorjoint_support" type="continuous">
    <parent link="rightrsupport"/>
    <child link="rightcastorsupport"/>
    <origin rpy="0 0 0" xyz="0.1175 -0.01 0.002"/>
    <axis rpy="0 3.14159265359 0" xyz="0 0 1"/>
    <limit effort="100" velocity="100"/>
    <!-- joint_properties damping="1.5" friction="1.5"/ -->
    <dynamics damping="0" friction="0.01"/>
  </joint>
  <link name="rightcastorsupport">
    <visual>
      <origin rpy="0 0 0" xyz="0 0 0"/>
      <geometry>
        <mesh filename="meshes/wheels/mcq_prototype_base_castor.dae"/>
      </geometry>
    </visual>
    <collision>
      <origin rpy="0 0 0" xyz="0 0 0"/>
      <geometry>
        <mesh filename="meshes/wheels/mcq_prototype_base_castor.dae"/>
      </geometry>
    </collision>
    <inertial>
      <mass value="1.5"/>
      <origin xyz="0 0 0"/>
      <inertia ixx="5e-05" ixy="0" ixz="0" iyy="5e-05" iyz="0" izz="7.5e-05"/>
      <!--Check these values -->
    </inertial>
  </link>
  <joint name="rightcastorjoint_wheel" type="continuous">
    <parent link="rightcastorsupport"/>
    <child link="rightcastorwheel"/>
    <origin rpy="0 0 0" xyz="-0.033 0.0 -0.071"/>
    <axis rpy="0 0 0" xyz="0 1 0"/>
    <limit effort="100" velocity="100"/>
    <joint_properties damping="0.1" friction="0.1"/>
  </joint>
  <link name="rightcastorwheel">
    <visual>
      <!-- HIGH RESOLUTION WHEELS -->
      <!-- xacro:if value="${hq}">
          <origin xyz="0 0 0" rpy="0 0 0" />
          <geometry>     
		<mesh filename="meshes/wheels/mcq_prototype_castor_wheel.dae" />
          </geometry>         
        </xacro:if -->
      <!-- LOW RESOLUTION WHEELS -->
      <!-- xacro:unless value="${hq}" -->
      <origin rpy="1.57079632679 0 0" xyz="0 0 0"/>
      <geometry>
        <cylinder length="0.025" radius="0.05"/>
        <!-- sphere radius="${caster_radius}"/ -->
      </geometry>
      <!-- /xacro:unless -->
    </visual>
    <collision>
      <origin rpy="1.57079632679 0 0" xyz="0 0 0"/>
      <!-- origin xyz="0 0 0" rpy="0 0 0" / -->
      <geometry>
        <!-- mesh filename="meshes/wheels/mcq_prototype_castor_wheel.dae" / -->
        <cylinder length="0.025" radius="0.05"/>
        <!-- sphere radius="${caster_radius}"/ -->
      </geometry>
      <surface>
        <bounce restitution_coefficient="1"/>
      </surface>
    </collision>
    <inertial>
      <mass value="0.25"/>
      <origin xyz="0 0 0"/>
      <inertia ixx="0.000169270833333" ixy="0" ixz="0" iyy="0.000169270833333" iyz="0" izz="0.0003125"/>
    </inertial>
  </link>
  <!-- Transmission is important to link the joints and the controller -->
  <transmission name="rightcastorsupport_joint_trans">
    <type>transmission_interface/SimpleTransmission</type>
    <joint name="rightcastorjoint_support">
      <hardwareInterface>hardware_interface/EffortJointInterface</hardwareInterface>
    </joint>
    <actuator name="rightcastorsupport_joint_motor">
      <mechanicalReduction>1</mechanicalReduction>
      <motorTorqueConstant>1</motorTorqueConstant>
    </actuator>
  </transmission>
  <transmission name="rightcastorwheel_joint_trans">
    <type>transmission_interface/SimpleTransmission</type>
    <joint name="rightcastorjoint_wheel">
      <hardwareInterface>hardware_interface/EffortJointInterface</hardwareInterface>
    </joint>
    <actuator name="rightcastorwheel_joint_motor">
      <mechanicalReduction>1</mechanicalReduction>
      <motorTorqueConstant>1</motorTorqueConstant>
    </actuator>
  </transmission>
  <!-- gazebo reference="${prefix}support">
			<mu1 value="5.0"/>
			<mu2 value="0.5"/>
			<kp value="10000000.0" />
			<kd value="1.0" />
			<fdir1 value="1 0 0"/>
      <turnGravityOff>false</turnGravityOff>
    </gazebo -->
  <gazebo reference="rightcastor_wheel">
    <mu1 value="100.0"/>
    <mu2 value="100.0"/>
    <!-- kp value="10000000.0" / -->
    <kp value="100000.0"/>
    <kd value="100.0"/>
    <!-- fdir1 value="1 0 0"/ -->
    <material>Gazebo/Black</material>
    <turnGravityOff>false</turnGravityOff>
  </gazebo>
  <!-- gazebo reference="${prefix}support">
			<mu1 value="5.0"/>
			<mu2 value="0.5"/>
			<kp value="10000000.0" />
			<kd value="1.0" />
			<fdir1 value="1 0 0"/>
      <turnGravityOff>false</turnGravityOff>
    </gazebo>
    
     <gazebo reference="${prefix}_wheel">
			<mu1 value="5.0"/>
			<mu2 value="0.5"/>
			<kp value="10000000.0" />
			<kd value="1.0" />
			<fdir1 value="1 0 0"/>
      <turnGravityOff>false</turnGravityOff>
    </gazebo -->
  <!--ROCKER BOGIE SUPPORT -->
  <!--joint name="${prefix}joint_support" type="continuous">
      <parent link="${parent}"/>
      <child link="${prefix}support"/>
      <insert_block name="origin" />
      <axis xyz="0 1 0" rpy="0 0 ${M_PI}" />
      <limit effort="100" velocity="100"/>
      <joint_properties damping="0.1" friction="0.1"/>
	</joint -->
  <joint name="leftjoint_rsupport" type="revolute">
    <parent link="base_link"/>
    <child link="leftrsupport"/>
    <origin rpy="0 0 0" xyz="0.1175 0.1725 0.0428"/>
    <axis rpy="0 0 3.14159265359" xyz="0 1 0"/>
    <limit effort="100" lower="-0.5" upper="0.5" velocity="100"/>
    <joint_properties damping="0.1" friction="0.1"/>
  </joint>
  <link name="leftrsupport">
    <visual>
      <origin rpy="0 0 0" xyz="0 0 0"/>
      <geometry>
        <mesh filename="meshes/rocker/mcq_prototype_rocker_l.dae"/>
      </geometry>
    </visual>
    <collision>
      <origin rpy="0 0 0" xyz="0 0 0"/>
      <geometry>
        <mesh filename="meshes/rocker/mcq_prototype_rocker_l.dae"/>
      </geometry>
    </collision>
    <inertial>
      <mass value="1.5"/>
      <origin xyz="0 0 0"/>
      <inertia ixx="5e-05" ixy="0" ixz="0" iyy="5e-05" iyz="0" izz="7.5e-05"/>
      <!--Check these values -->
    </inertial>
  </link>
  <!-- Transmission is important to link the joints and the controller -->
  <transmission name="leftrsupport_joint_trans">
    <type>transmission_interface/SimpleTransmission</type>
    <joint name="leftjoint_rsupport">
      <hardwareInterface>hardware_interface/EffortJointInterface</hardwareInterface>
    </joint>
    <actuator name="leftrsupport_joint_motor">
      <mechanicalReduction>1</mechanicalReduction>
      <motorTorqueConstant>1</motorTorqueConstant>
    </actuator>
  </transmission>
  <!-- xacro:rubber_wheel prefix="$(arg prefix)wheel" parent="$(arg prefix)support" reflect="true" hq="${hq}">
		<origin xyz="${wheel_offset_x} ${wheel_offset_y} ${wheel_offset_z}" rpy="0 0 0"/>
	</xacro:rubber_wheel -->
  <!--WHEEL TIRE -->
  <joint name="left_wheel_joint" type="continuous">
    <parent link="leftrsupport"/>
    <child link="left_wheel_link"/>
    <origin rpy="0 0 0" xyz="-0.1175 0.079 -0.0428"/>
    <axis rpy="0 0 0" xyz="0 1 0"/>
    <limit effort="100" velocity="100"/>
    <joint_properties damping="0.0" friction="0.0"/>
  </joint>
  <link name="left_wheel_link">
    <visual>
      <!-- HIGH RESOLUTION WHEELS -->
      <!-- LOW RESOLUTION WHEELS -->
      <origin rpy="1.57079632679 0 0" xyz="0 0 0"/>
      <geometry>
        <cylinder length="0.025" radius="0.0756"/>
      </geometry>
    </visual>
    <collision>
      <origin rpy="1.57079632679 0 0" xyz="0 0 0"/>
      <geometry>
        <cylinder length="0.025" radius="0.0756"/>
      </geometry>
    </collision>
    <inertial>
      <mass value="0.25"/>
      <origin xyz="0 0 0"/>
      <inertia ixx="0.000370230833333" ixy="0" ixz="0" iyy="0.000370230833333" iyz="0" izz="0.00071442"/>
    </inertial>
  </link>
  <!-- Transmission is important to link the joints and the controller (see rb_theron_control/config/rb_theron_control.yaml)-->
  <transmission name="left_wheel_joint_trans">
    <type>transmission_interface/SimpleTransmission</type>
    <joint name="left_wheel_joint">
      <!-- for the gazebo plugin -->
      <!--hardwareInterface>EffortJointInterface</hardwareInterface-->
      <!-- for ros control controller -->
      <hardwareInterface>hardware_interface/VelocityJointInterface</hardwareInterface>
    </joint>
    <actuator name="left_wheel_joint_motor">
      <mechanicalReduction>1</mechanicalReduction>
      <motorTorqueConstant>20</motorTorqueConstant>
    </actuator>
  </transmission>
  <gazebo reference="left_wheel_link">
    <!-- mu1 value="5.0"/>
			<mu2 value="0.5"/>
			<kp value="10000000.0" />
			<kd value="1.0" />
			<fdir1 value="1 0 0"/>
			<material>Gazebo/Yellow</material>
			<turnGravityOff>false</turnGravityOff -->
    <!-- mu1 value="5.0"/>
			<mu2 value="0.5"/ -->
    <mu1 value="100.0"/>
    <mu2 value="100.0"/>
    <!-- kp value="100000.0" / -->
    <kp value="500000.0"/>
    <kd value="1.0"/>
    <!-- fdir1 value="1 0 0"/ -->
    <material>Gazebo/Yellow</material>
    <turnGravityOff>false</turnGravityOff>
    <!--kp>500000.0</kp>
			<kd>10.0</kd>
			<mu1>10</mu1>
			<mu2>10</mu2>
			<fdir1>1 0 0</fdir1-->
    <!--minDepth>0.001</minDepth-->
    <!--material>Gazebo/Black</material-->
    <!--mu1 value="10"/>
			<mu2 value="5"/>
			<kp value="500000.0" />
			<kd value="10.0" />
			<fdir1 value="1 0 0"/>
			<material>Gazebo/Yellow</material>
			<turnGravityOff>false</turnGravityOff-->
  </gazebo>
  <!--gazebo reference="${name}_wheel_link">
			<kp>500000.0</kp>
			<kd>10.0</kd>
			<mu1>10</mu1>
			<mu2>10</mu2>
			<fdir1>1 0 0</fdir1>
			<maxVel>1.0</maxVel>
			<minDepth>0.003</minDepth>
			<material>Gazebo/Yellow</material>
			<turnGravityOff>false</turnGravityOff>
			<implicitSpringDamper>1</implicitSpringDamper>
		</gazebo-->
  <!-- xacro:caster prefix="$(arg prefix)left" parent="$(arg prefix)support" hq="${hq}">
		<origin xyz="${caster_offset_x} ${caster_offset_y} ${caster_offset_z}" rpy="0 0 0"/>
	</xacro:caster -->
  <!--CASTER SUPPORT -->
  <joint name="leftcastorjoint_support" type="continuous">
    <parent link="leftrsupport"/>
    <child link="leftcastorsupport"/>
    <origin rpy="0 0 0" xyz="0.1175 0.01 0.002"/>
    <axis rpy="0 3.14159265359 0" xyz="0 0 1"/>
    <limit effort="100" velocity="100"/>
    <!-- joint_properties damping="1.5" friction="1.5"/ -->
    <dynamics damping="0" friction="0.01"/>
  </joint>
  <link name="leftcastorsupport">
    <visual>
      <origin rpy="0 0 0" xyz="0 0 0"/>
      <geometry>
        <mesh filename="meshes/wheels/mcq_prototype_base_castor.dae"/>
      </geometry>
    </visual>
    <collision>
      <origin rpy="0 0 0" xyz="0 0 0"/>
      <geometry>
        <mesh filename="meshes/wheels/mcq_prototype_base_castor.dae"/>
      </geometry>
    </collision>
    <inertial>
      <mass value="1.5"/>
      <origin xyz="0 0 0"/>
      <inertia ixx="5e-05" ixy="0" ixz="0" iyy="5e-05" iyz="0" izz="7.5e-05"/>
      <!--Check these values -->
    </inertial>
  </link>
  <joint name="leftcastorjoint_wheel" type="continuous">
    <parent link="leftcastorsupport"/>
    <child link="leftcastorwheel"/>
    <origin rpy="0 0 0" xyz="-0.033 0.0 -0.071"/>
    <axis rpy="0 0 0" xyz="0 1 0"/>
    <limit effort="100" velocity="100"/>
    <joint_properties damping="0.1" friction="0.1"/>
  </joint>
  <link name="leftcastorwheel">
    <visual>
      <!-- HIGH RESOLUTION WHEELS -->
      <!-- xacro:if value="${hq}">
          <origin xyz="0 0 0" rpy="0 0 0" />
          <geometry>     
		<mesh filename="meshes/wheels/mcq_prototype_castor_wheel.dae" />
          </geometry>         
        </xacro:if -->
      <!-- LOW RESOLUTION WHEELS -->
      <!-- xacro:unless value="${hq}" -->
      <origin rpy="1.57079632679 0 0" xyz="0 0 0"/>
      <geometry>
        <cylinder length="0.025" radius="0.05"/>
        <!-- sphere radius="${caster_radius}"/ -->
      </geometry>
      <!-- /xacro:unless -->
    </visual>
    <collision>
      <origin rpy="1.57079632679 0 0" xyz="0 0 0"/>
      <!-- origin xyz="0 0 0" rpy="0 0 0" / -->
      <geometry>
        <!-- mesh filename="meshes/wheels/mcq_prototype_castor_wheel.dae" / -->
        <cylinder length="0.025" radius="0.05"/>
        <!-- sphere radius="${caster_radius}"/ -->
      </geometry>
      <surface>
        <bounce restitution_coefficient="1"/>
      </surface>
    </collision>
    <inertial>
      <mass value="0.25"/>
      <origin xyz="0 0 0"/>
      <inertia ixx="0.000169270833333" ixy="0" ixz="0" iyy="0.000169270833333" iyz="0" izz="0.0003125"/>
    </inertial>
  </link>
  <!-- Transmission is important to link the joints and the controller -->
  <transmission name="leftcastorsupport_joint_trans">
    <type>transmission_interface/SimpleTransmission</type>
    <joint name="leftcastorjoint_support">
      <hardwareInterface>hardware_interface/EffortJointInterface</hardwareInterface>
    </joint>
    <actuator name="leftcastorsupport_joint_motor">
      <mechanicalReduction>1</mechanicalReduction>
      <motorTorqueConstant>1</motorTorqueConstant>
    </actuator>
  </transmission>
  <transmission name="leftcastorwheel_joint_trans">
    <type>transmission_interface/SimpleTransmission</type>
    <joint name="leftcastorjoint_wheel">
      <hardwareInterface>hardware_interface/EffortJointInterface</hardwareInterface>
    </joint>
    <actuator name="leftcastorwheel_joint_motor">
      <mechanicalReduction>1</mechanicalReduction>
      <motorTorqueConstant>1</motorTorqueConstant>
    </actuator>
  </transmission>
  <!-- gazebo reference="${prefix}support">
			<mu1 value="5.0"/>
			<mu2 value="0.5"/>
			<kp value="10000000.0" />
			<kd value="1.0" />
			<fdir1 value="1 0 0"/>
      <turnGravityOff>false</turnGravityOff>
    </gazebo -->
  <gazebo reference="leftcastor_wheel">
    <mu1 value="100.0"/>
    <mu2 value="100.0"/>
    <!-- kp value="10000000.0" / -->
    <kp value="100000.0"/>
    <kd value="100.0"/>
    <!-- fdir1 value="1 0 0"/ -->
    <material>Gazebo/Black</material>
    <turnGravityOff>false</turnGravityOff>
  </gazebo>
  <!-- gazebo reference="${prefix}support">
			<mu1 value="5.0"/>
			<mu2 value="0.5"/>
			<kp value="10000000.0" />
			<kd value="1.0" />
			<fdir1 value="1 0 0"/>
      <turnGravityOff>false</turnGravityOff>
    </gazebo>
    
     <gazebo reference="${prefix}_wheel">
			<mu1 value="5.0"/>
			<mu2 value="0.5"/>
			<kp value="10000000.0" />
			<kd value="1.0" />
			<fdir1 value="1 0 0"/>
      <turnGravityOff>false</turnGravityOff>
    </gazebo -->
  <!--CASTER SUPPORT -->
  <joint name="leftjoint_support" type="continuous">
    <parent link="base_link"/>
    <child link="leftsupport"/>
    <origin rpy="0 0 0" xyz="-0.235 0.1725 0.0428"/>
    <axis rpy="0 3.14159265359 0" xyz="0 0 1"/>
    <limit effort="100" velocity="100"/>
    <!-- joint_properties damping="1.5" friction="1.5"/ -->
    <dynamics damping="0" friction="0.01"/>
  </joint>
  <link name="leftsupport">
    <visual>
      <origin rpy="0 0 0" xyz="0 0 0"/>
      <geometry>
        <mesh filename="meshes/wheels/mcq_prototype_base_castor.dae"/>
      </geometry>
    </visual>
    <collision>
      <origin rpy="0 0 0" xyz="0 0 0"/>
      <geometry>
        <mesh filename="meshes/wheels/mcq_prototype_base_castor.dae"/>
      </geometry>
    </collision>
    <inertial>
      <mass value="1.5"/>
      <origin xyz="0 0 0"/>
      <inertia ixx="5e-05" ixy="0" ixz="0" iyy="5e-05" iyz="0" izz="7.5e-05"/>
      <!--Check these values -->
    </inertial>
  </link>
  <joint name="leftjoint_wheel" type="continuous">
    <parent link="leftsupport"/>
    <child link="leftwheel"/>
    <origin rpy="0 0 0" xyz="-0.033 0.0 -0.071"/>
    <axis rpy="0 0 0" xyz="0 1 0"/>
    <limit effort="100" velocity="100"/>
    <joint_properties damping="0.1" friction="0.1"/>
  </joint>
  <link name="leftwheel">
    <visual>
      <!-- HIGH RESOLUTION WHEELS -->
      <!-- xacro:if value="${hq}">
          <origin xyz="0 0 0" rpy="0 0 0" />
          <geometry>     
		<mesh filename="meshes/wheels/mcq_prototype_castor_wheel.dae" />
          </geometry>         
        </xacro:if -->
      <!-- LOW RESOLUTION WHEELS -->
      <!-- xacro:unless value="${hq}" -->
      <origin rpy="1.57079632679 0 0" xyz="0 0 0"/>
      <geometry>
        <cylinder length="0.025" radius="0.05"/>
        <!-- sphere radius="${caster_radius}"/ -->
      </geometry>
      <!-- /xacro:unless -->
    </visual>
    <collision>
      <origin rpy="1.57079632679 0 0" xyz="0 0 0"/>
      <!-- origin xyz="0 0 0" rpy="0 0 0" / -->
      <geometry>
        <!-- mesh filename="meshes/wheels/mcq_prototype_castor_wheel.dae" / -->
        <cylinder length="0.025" radius="0.05"/>
        <!-- sphere radius="${caster_radius}"/ -->
      </geometry>
      <surface>
        <bounce restitution_coefficient="1"/>
      </surface>
    </collision>
    <inertial>
      <mass value="0.25"/>
      <origin xyz="0 0 0"/>
      <inertia ixx="0.000169270833333" ixy="0" ixz="0" iyy="0.000169270833333" iyz="0" izz="0.0003125"/>
    </inertial>
  </link>
  <!-- Transmission is important to link the joints and the controller -->
  <transmission name="leftsupport_joint_trans">
    <type>transmission_interface/SimpleTransmission</type>
    <joint name="leftjoint_support">
      <hardwareInterface>hardware_interface/EffortJointInterface</hardwareInterface>
    </joint>
    <actuator name="leftsupport_joint_motor">
      <mechanicalReduction>1</mechanicalReduction>
      <motorTorqueConstant>1</motorTorqueConstant>
    </actuator>
  </transmission>
  <transmission name="leftwheel_joint_trans">
    <type>transmission_interface/SimpleTransmission</type>
    <joint name="leftjoint_wheel">
      <hardwareInterface>hardware_interface/EffortJointInterface</hardwareInterface>
    </joint>
    <actuator name="leftwheel_joint_motor">
      <mechanicalReduction>1</mechanicalReduction>
      <motorTorqueConstant>1</motorTorqueConstant>
    </actuator>
  </transmission>
  <!-- gazebo reference="${prefix}support">
			<mu1 value="5.0"/>
			<mu2 value="0.5"/>
			<kp value="10000000.0" />
			<kd value="1.0" />
			<fdir1 value="1 0 0"/>
      <turnGravityOff>false</turnGravityOff>
    </gazebo -->
  <gazebo reference="left_wheel">
    <mu1 value="100.0"/>
    <mu2 value="100.0"/>
    <!-- kp value="10000000.0" / -->
    <kp value="100000.0"/>
    <kd value="100.0"/>
    <!-- fdir1 value="1 0 0"/ -->
    <material>Gazebo/Black</material>
    <turnGravityOff>false</turnGravityOff>
  </gazebo>
  <!--CASTER SUPPORT -->
  <joint name="rightjoint_support" type="continuous">
    <parent link="base_link"/>
    <child link="rightsupport"/>
    <origin rpy="0 0 0" xyz="-0.235 -0.1725 0.0428"/>
    <axis rpy="0 3.14159265359 0" xyz="0 0 1"/>
    <limit effort="100" velocity="100"/>
    <!-- joint_properties damping="1.5" friction="1.5"/ -->
    <dynamics damping="0" friction="0.01"/>
  </joint>
  <link name="rightsupport">
    <visual>
      <origin rpy="0 0 0" xyz="0 0 0"/>
      <geometry>
        <mesh filename="meshes/wheels/mcq_prototype_base_castor.dae"/>
      </geometry>
    </visual>
    <collision>
      <origin rpy="0 0 0" xyz="0 0 0"/>
      <geometry>
        <mesh filename="meshes/wheels/mcq_prototype_base_castor.dae"/>
      </geometry>
    </collision>
    <inertial>
      <mass value="1.5"/>
      <origin xyz="0 0 0"/>
      <inertia ixx="5e-05" ixy="0" ixz="0" iyy="5e-05" iyz="0" izz="7.5e-05"/>
      <!--Check these values -->
    </inertial>
  </link>
  <joint name="rightjoint_wheel" type="continuous">
    <parent link="rightsupport"/>
    <child link="rightwheel"/>
    <origin rpy="0 0 0" xyz="-0.033 0.0 -0.071"/>
    <axis rpy="0 0 0" xyz="0 1 0"/>
    <limit effort="100" velocity="100"/>
    <joint_properties damping="0.1" friction="0.1"/>
  </joint>
  <link name="rightwheel">
    <visual>
      <!-- HIGH RESOLUTION WHEELS -->
      <!-- xacro:if value="${hq}">
          <origin xyz="0 0 0" rpy="0 0 0" />
          <geometry>     
		<mesh filename="meshes/wheels/mcq_prototype_castor_wheel.dae" />
          </geometry>         
        </xacro:if -->
      <!-- LOW RESOLUTION WHEELS -->
      <!-- xacro:unless value="${hq}" -->
      <origin rpy="1.57079632679 0 0" xyz="0 0 0"/>
      <geometry>
        <cylinder length="0.025" radius="0.05"/>
        <!-- sphere radius="${caster_radius}"/ -->
      </geometry>
      <!-- /xacro:unless -->
    </visual>
    <collision>
      <origin rpy="1.57079632679 0 0" xyz="0 0 0"/>
      <!-- origin xyz="0 0 0" rpy="0 0 0" / -->
      <geometry>
        <!-- mesh filename="meshes/wheels/mcq_prototype_castor_wheel.dae" / -->
        <cylinder length="0.025" radius="0.05"/>
        <!-- sphere radius="${caster_radius}"/ -->
      </geometry>
      <surface>
        <bounce restitution_coefficient="1"/>
      </surface>
    </collision>
    <inertial>
      <mass value="0.25"/>
      <origin xyz="0 0 0"/>
      <inertia ixx="0.000169270833333" ixy="0" ixz="0" iyy="0.000169270833333" iyz="0" izz="0.0003125"/>
    </inertial>
  </link>
  <!-- Transmission is important to link the joints and the controller -->
  <transmission name="rightsupport_joint_trans">
    <type>transmission_interface/SimpleTransmission</type>
    <joint name="rightjoint_support">
      <hardwareInterface>hardware_interface/EffortJointInterface</hardwareInterface>
    </joint>
    <actuator name="rightsupport_joint_motor">
      <mechanicalReduction>1</mechanicalReduction>
      <motorTorqueConstant>1</motorTorqueConstant>
    </actuator>
  </transmission>
  <transmission name="rightwheel_joint_trans">
    <type>transmission_interface/SimpleTransmission</type>
    <joint name="rightjoint_wheel">
      <hardwareInterface>hardware_interface/EffortJointInterface</hardwareInterface>
    </joint>
    <actuator name="rightwheel_joint_motor">
      <mechanicalReduction>1</mechanicalReduction>
      <motorTorqueConstant>1</motorTorqueConstant>
    </actuator>
  </transmission>
  <!-- gazebo reference="${prefix}support">
			<mu1 value="5.0"/>
			<mu2 value="0.5"/>
			<kp value="10000000.0" />
			<kd value="1.0" />
			<fdir1 value="1 0 0"/>
      <turnGravityOff>false</turnGravityOff>
    </gazebo -->
  <gazebo reference="right_wheel">
    <mu1 value="100.0"/>
    <mu2 value="100.0"/>
    <!-- kp value="10000000.0" / -->
    <kp value="100000.0"/>
    <kd value="100.0"/>
    <!-- fdir1 value="1 0 0"/ -->
    <material>Gazebo/Black</material>
    <turnGravityOff>false</turnGravityOff>
  </gazebo>
  <!-- camera body, with origin at bottom screw mount -->
  <joint name="front_realsense_camera_camera_joint" type="fixed">
    <origin rpy="0 0 0" xyz="0.3305 0.0 0.1468"/>
    <parent link="base_link"/>
    <child link="front_realsense_camera_camera_link"/>
  </joint>
  <link name="front_realsense_camera_camera_link">
    <visual>
      <!-- origin xyz="0 ${-r430_cam_mount_from_center_offset} ${r430_cam_height/2}" rpy="${M_PI/2} 0 ${M_PI/2}"/ -->
      <origin rpy="0 0 0" xyz="0 -0.0 0"/>
      <geometry>
        <!-- box size="${r430_cam_width} ${r430_cam_height} ${r430_cam_depth}"/ -->
        <mesh filename="meshes/sensors/intel_r430.dae"/>
      </geometry>
      <material name="aluminum">
        <color rgba="0.5 0.5 0.5 1"/>
      </material>
    </visual>
    <collision>
      <origin rpy="0 0 0" xyz="-0.0125 0.0 0.0"/>
      <geometry>
        <box size="0.025 0.1 0.025"/>
      </geometry>
    </collision>
    <inertial>
      <origin rpy="0 0 0" xyz="-0.0125 0.0 0.0"/>
      <mass value="0.1"/>
      <inertia ixx="7.27083333333e-05" ixy="0" ixz="0" iyy="1.04166666667e-05" iyz="0" izz="7.27083333333e-05"/>
    </inertial>
  </link>
  <!-- camera depth joints and links -->
  <joint name="front_realsense_camera_camera_depth_joint" type="fixed">
    <origin rpy="0 0 0" xyz="0.0 -0.0115 0.0"/>
    <parent link="front_realsense_camera_camera_link"/>
    <child link="front_realsense_camera_camera_depth_frame"/>
  </joint>
  <link name="front_realsense_camera_camera_depth_frame"/>
  <joint name="front_realsense_camera_camera_depth_optical_joint" type="fixed">
    <origin rpy="-1.57079632679 0 -1.57079632679" xyz="0 0 0"/>
    <parent link="front_realsense_camera_camera_depth_frame"/>
    <child link="front_realsense_camera_camera_depth_optical_frame"/>
  </joint>
  <link name="front_realsense_camera_camera_depth_optical_frame"/>
  <!-- camera left IR joints and links -->
  <joint name="front_realsense_camera_camera_left_ir_joint" type="fixed">
    <origin rpy="0 0 0" xyz="0 -0.021 0"/>
    <parent link="front_realsense_camera_camera_depth_frame"/>
    <child link="front_realsense_camera_camera_left_ir_frame"/>
  </joint>
  <link name="front_realsense_camera_camera_left_ir_frame"/>
  <joint name="front_realsense_camera_camera_left_ir_optical_joint" type="fixed">
    <origin rpy="-1.57079632679 0 -1.57079632679" xyz="0 0 0"/>
    <parent link="front_realsense_camera_camera_left_ir_frame"/>
    <child link="front_realsense_camera_camera_left_ir_optical_frame"/>
  </joint>
  <link name="front_realsense_camera_camera_left_ir_optical_frame"/>
  <!-- camera right IR joints and links -->
  <joint name="front_realsense_camera_camera_right_ir_joint" type="fixed">
    <origin rpy="0 0 0" xyz="0 0.029 0"/>
    <parent link="front_realsense_camera_camera_depth_frame"/>
    <child link="front_realsense_camera_camera_right_ir_frame"/>
  </joint>
  <link name="front_realsense_camera_camera_right_ir_frame"/>
  <joint name="front_realsense_camera_camera_right_ir_optical_joint" type="fixed">
    <origin rpy="-1.57079632679 0 -1.57079632679" xyz="0 0 0"/>
    <parent link="front_realsense_camera_camera_right_ir_frame"/>
    <child link="front_realsense_camera_camera_right_ir_optical_frame"/>
  </joint>
  <link name="front_realsense_camera_camera_right_ir_optical_frame"/>
  <!-- camera fisheye joints and links -->
  <joint name="front_realsense_camera_camera_fisheye_joint" type="fixed">
    <origin rpy="0 0 0" xyz="0 0.044 0"/>
    <parent link="front_realsense_camera_camera_depth_frame"/>
    <child link="front_realsense_camera_camera_fisheye_frame"/>
  </joint>
  <link name="front_realsense_camera_camera_fisheye_frame"/>
  <joint name="front_realsense_camera_camera_fisheye_optical_joint" type="fixed">
    <origin rpy="-1.57079632679 0 -1.57079632679" xyz="0 0 0"/>
    <parent link="front_realsense_camera_camera_fisheye_frame"/>
    <child link="front_realsense_camera_camera_fisheye_optical_frame"/>
  </joint>
  <link name="front_realsense_camera_camera_fisheye_optical_frame"/>
  <!-- gazebo reference="${prefix}_rgb_base_link" -->
  <gazebo reference="front_realsense_camera_camera_link">
    <sensor name="front_realsense_camera_depth_sensor" type="depth">
      <always_on>true</always_on>
      <update_rate>15.0</update_rate>
      <camera>
        <horizontal_fov>1.59174027782</horizontal_fov>
        <image>
          <format>R8G8B8</format>
          <width>640</width>
          <height>480</height>
        </image>
        <clip>
          <near>0.3</near>
          <far>10.0</far>
        </clip>
      </camera>
      <plugin filename="libgazebo_ros_openni_kinect.so" name="front_realsense_camera_controller">
        <cameraName>front_realsense_camera</cameraName>
        <alwaysOn>true</alwaysOn>
        <updateRate>10</updateRate>
        <imageTopicName>rgb/image_raw</imageTopicName>
        <depthImageTopicName>depth/image_raw</depthImageTopicName>
        <pointCloudTopicName>depth/points</pointCloudTopicName>
        <cameraInfoTopicName>rgb/camera_info</cameraInfoTopicName>
        <depthImageCameraInfoTopicName>depth/camera_info</depthImageCameraInfoTopicName>
        <frameName>/front_realsense_camera_camera_depth_optical_frame</frameName>
        <baseline>0.1</baseline>
        <distortion_k1>0.0</distortion_k1>
        <distortion_k2>0.0</distortion_k2>
        <distortion_k3>0.0</distortion_k3>
        <distortion_t1>0.0</distortion_t1>
        <distortion_t2>0.0</distortion_t2>
        <pointCloudCutoff>0.4</pointCloudCutoff>
      </plugin>
    </sensor>
  </gazebo>
  <joint name="front_rgbd_camera_joint" type="fixed">
    <origin rpy="0 0 0" xyz="0.25 0 0.265"/>
    <parent link="base_link"/>
    <child link="front_rgbd_camera_link"/>
  </joint>
  <link name="front_rgbd_camera_link">
    <visual>
      <origin rpy="0 0 0" xyz="0 0 0"/>
      <geometry>
        <mesh filename="meshes/sensors/orbbec_astra.dae"/>
      </geometry>
    </visual>
    <collision>
      <geometry>
        <mesh filename="meshes/sensors/orbbec_astra.dae"/>
      </geometry>
    </collision>
    <inertial>
      <mass value="0.001"/>
      <origin xyz="0.0 0.0 0.0"/>
      <inertia ixx="2.34375e-06" ixy="0" ixz="0" iyy="2.08333333333e-07" iyz="0" izz="2.40208333333e-06"/>
    </inertial>
  </link>
  <joint name="front_rgbd_camera_rgb_joint" type="fixed">
    <origin rpy="0.0 0.0 0.0" xyz="0.0 0.0 0.0"/>
    <parent link="front_rgbd_camera_link"/>
    <child link="front_rgbd_camera_rgb_frame"/>
  </joint>
  <link name="front_rgbd_camera_rgb_frame">
    <inertial>
      <mass value="0.297"/>
      <origin xyz="-0.02 -0.0125 0.0"/>
      <inertia ixx="0.00069609375" ixy="0" ixz="0" iyy="6.1875e-05" iyz="0" izz="0.00071341875"/>
    </inertial>
  </link>
  <joint name="front_rgbd_camera_rgb_optical_joint" type="fixed">
    <origin rpy="-1.57079632679 0 -1.57079632679" xyz="0.0 0.0 0.0"/>
    <parent link="front_rgbd_camera_rgb_frame"/>
    <child link="front_rgbd_camera_rgb_optical_frame"/>
  </joint>
  <link name="front_rgbd_camera_rgb_optical_frame">
    <inertial>
      <mass value="0.001"/>
      <origin rpy="1.57079632679 0 1.57079632679" xyz="0 0 0"/>
      <inertia ixx="2.34375e-06" ixy="0" ixz="0" iyy="2.08333333333e-07" iyz="0" izz="2.40208333333e-06"/>
    </inertial>
  </link>
  <joint name="front_rgbd_camera_depth_joint" type="fixed">
    <origin rpy="0 0 0" xyz="0.0 0.0 0.0"/>
    <parent link="front_rgbd_camera_link"/>
    <child link="front_rgbd_camera_depth_frame"/>
  </joint>
  <link name="front_rgbd_camera_depth_frame">
    <inertial>
      <mass value="0.001"/>
      <origin xyz="0 0 0"/>
      <inertia ixx="2.34375e-06" ixy="0" ixz="0" iyy="2.08333333333e-07" iyz="0" izz="2.40208333333e-06"/>
    </inertial>
  </link>
  <joint name="front_rgbd_camera_depth_optical_joint" type="fixed">
    <origin rpy="-1.57079632679 0 -1.57079632679" xyz="0 0 0"/>
    <parent link="front_rgbd_camera_depth_frame"/>
    <child link="front_rgbd_camera_depth_optical_frame"/>
  </joint>
  <link name="front_rgbd_camera_depth_optical_frame">
    <inertial>
      <mass value="0.001"/>
      <origin xyz="0 0 0"/>
      <inertia ixx="2.34375e-06" ixy="0" ixz="0" iyy="2.08333333333e-07" iyz="0" izz="2.40208333333e-06"/>
    </inertial>
  </link>
  <joint name="imu_joint" type="fixed">
    <axis xyz="1 0 0"/>
    <!--origin xyz="0 0 0.2825"/-->
    <origin rpy="0 0 0" xyz="-0.1975 0.0 0.1598"/>
    <parent link="base_link"/>
    <child link="imu_link"/>
  </joint>
  <link name="imu_link">
    <inertial>
      <origin rpy="0 0 0" xyz="0.0 0 0.01"/>
      <mass value="0.05"/>
      <inertia ixx="3.33333333333e-06" ixy="0" ixz="0" iyy="3.33333333333e-06" iyz="0" izz="3.33333333333e-06"/>
    </inertial>
    <visual>
      <origin rpy="0 0 0" xyz="0 0 0"/>
      <geometry>
        <box size="0.001 0.001 0.001"/>
      </geometry>
    </visual>
    <collision>
      <origin rpy="0 0 0" xyz="0 0 0"/>
      <geometry>
        <box size=".001 .001 .001"/>
      </geometry>
    </collision>
  </link>

  <joint name="front_laser_base_joint" type="fixed">
    <origin rpy="0 3.1416 3.1416" xyz="0.250 0.0 0.1643"/>
    <parent link="base_link"/>
    <child link="front_laser_base_link"/>
  </joint>
  <link name="front_laser_base_link">
    <collision>
      <origin rpy="0 0 0" xyz="0 0 0"/>
      <geometry>
        <!--<box size="0.106 0.094 0.152"/>-->
        <!--<cylinder radius="0.058" length="0.152"/>-->
        <mesh filename="meshes/sensors/sick_nanoscan3.dae"/>
      </geometry>
    </collision>
    <visual>
      <origin rpy="0 0 0" xyz="0 0 0"/>
      <geometry>
        <mesh filename="meshes/sensors/sick_nanoscan3.dae"/>
      </geometry>
    </visual>
    <inertial>
      <mass value="0.67"/>
      <origin rpy="0 0 0" xyz="0 0 0.04"/>
      <inertia ixx="0.000922386766667" ixy="0" ixz="0" iyy="0.000922386766667" iyz="0" izz="0.00113010686667"/>
      <!-- Datasheet dimensional drawing: 100.6 mm x 100.6 mm x 80 mm without connectors -->
    </inertial>
  </link>
  <joint name="front_laser_joint" type="fixed">
    <parent link="front_laser_base_link"/>
    <child link="front_laser_link"/>
    <origin rpy="3.14159265359 0 0" xyz="0.0 0.0 0.0505"/>
  </joint>
  <link name="front_laser_link"/>

  <joint name="top_laser_base_joint" type="fixed">
    <origin rpy="0 0 0" xyz="0.250 0.0 0.2896"/>
    <parent link="base_link"/>
    <child link="top_laser_base_link"/>
  </joint>
  <link name="top_laser_base_link">
    <collision>
      <origin rpy="0 0 0" xyz="0 0 0"/>
      <geometry>
        <!--<box size="0.106 0.094 0.152"/>-->
        <!--<cylinder radius="0.058" length="0.152"/>-->
        <mesh filename="meshes/sensors/sick_nanoscan3.dae"/>
      </geometry>
    </collision>
    <visual>
      <origin rpy="0 0 0" xyz="0 0 0"/>
      <geometry>
        <mesh filename="meshes/sensors/sick_nanoscan3.dae"/>
      </geometry>
    </visual>
    <inertial>
      <mass value="0.67"/>
      <origin rpy="0 0 0" xyz="0 0 0.04"/>
      <inertia ixx="0.000922386766667" ixy="0" ixz="0" iyy="0.000922386766667" iyz="0" izz="0.00113010686667"/>
      <!-- Datasheet dimensional drawing: 100.6 mm x 100.6 mm x 80 mm without connectors -->
    </inertial>
  </link>
  <joint name="top_laser_joint" type="fixed">
    <parent link="top_laser_base_link"/>
    <child link="top_laser_link"/>
    <origin rpy="0 0 0" xyz="0.0 0 0.0505"/>
  </joint>
  <link name="top_laser_link"/>
</robot>
